Workbook

Sheet Raw Atomic Data (Pro)
A1: Participant | B1: Provider segment | C1: Category | D1: Theme | E1: Type | F1: Observation | G1: Quote | H1: First occurrence (participant x theme x type)
A2: Ami | B2: Pro | C2: Context and provider model | D2: provider-background | E2: fact | F2: She is 60 years old ("I am 60. I just turned 60, which was hard to believe.") and worked as a music teacher for 32 years before retiring. | G2: I am 60. I just turned 60, which was hard to believe. | H2: =IF(COUNTIFS($D$2:D2,D2,$E$2:E2,E2,$A$2:A2,A2)=1,1,0) -> 1
A3: Ami | B3: Pro | C3: Context and provider model | D3: provider-background | E3: fact | F3: She retired from teaching music and singing in 2024 after 32 years ("I retired um in 2024 and I taught for 32 years"). | G3: I retired um in 2024 and I taught for 32 years | H3: =IF(COUNTIFS($D$2:D3,D3,$E$2:E3,E3,$A$2:A3,A3)=1,1,0) -> 0
A4: Ami | B4: Pro | C4: Context and provider model | D4: provider-background | E4: fact | F4: She currently manages roughly 10 regular Rover clients by her own rough estimate, and at the time of the interview was only taking current/regular clients rather than accepting new ones ("I probably have maybe like I 10 like that's a rough estimate right now" and "at this point, I'm only doing taking, um, current clients. I'm not accepting new clients."). | G4: I probably have maybe like I 10 like that's a rough estimate right now | H4: =IF(COUNTIFS($D$2:D4,D4,$E$2:E4,E4,$A$2:A4,A4)=1,1,0) -> 0
A5: Ami | B5: Pro | C5: Context and provider model | D5: business-model-fit | E5: fact | F5: Pet sitting fits within her retirement schedule; she describes the workload as sporadic, with busy spurts followed by lulls, and says a typical day has anywhere from about two to six visits ("it fits within a retirement schedule really well"; "it's also very sporadic like sometimes I'll get really really busy and then I get a little bit a lull and then I get really busy and then a lull"; "I'll have anywhere from like two to two to six visits the most"). | G5: it fits within a retirement schedule really well | H5: =IF(COUNTIFS($D$2:D5,D5,$E$2:E5,E5,$A$2:A5,A5)=1,1,0) -> 1
A6: Ami | B6: Pro | C6: Context and provider model | D6: provider-background | E6: fact | F6: She is married with three kids and currently owns two dogs and a cat of her own ("I have two dogs and a cat" and "my three kids, my husband"). | G6: I have two dogs and a cat | H6: =IF(COUNTIFS($D$2:D6,D6,$E$2:E6,E6,$A$2:A6,A6)=1,1,0) -> 0
A7: Ami | B7: Pro | C7: Context and provider model | D7: business-model-fit | E7: value-statement | F7: Before starting on Rover, she originally planned to launch her own independent pet-sitting business, saying she thought she'd "build a, you know, a Google survey" and put out "business cards and I'll put that around my neighborhood" ("I originally was going to try to do something like that on my own"), but decided to start with Rover first, and only after doing so did she realize Rover already offered the organizational setup she would have had to build herself, which is why she stuck with it ("I think I'll just I'll start with Rover"; "then then I realized that it it was easier just to I like the way Rover was set up because I didn't have to do all of that"). | G7: I originally was going to try to do something like that on my own | H7: =IF(COUNTIFS($D$2:D7,D7,$E$2:E7,E7,$A$2:A7,A7)=1,1,0) -> 1
A8: Ami | B8: Pro | C8: Context and provider model | D8: onboarding-signup-process | E8: value-statement | F8: She says the background check requirement was part of what convinced her to stick with Rover, since it matched the kind of screening she was used to from her teaching career ("I think the fact that uh they wanted to do a background check which was great because you know coming out of teaching I was used to having that you know kind of screening being done which I thought was good"). | G8: I think the fact that uh they wanted to do a background check which was great because you know coming out of teaching I was used to having that you know kind of screening being done which I thought was good | H8: =IF(COUNTIFS($D$2:D8,D8,$E$2:E8,E8,$A$2:A8,A8)=1,1,0) -> 1
A9: Ami | B9: Pro | C9: Context and provider model | D9: onboarding-signup-process | E9: value-statement | F9: She found account setup easy and, once her background check and approval went through, quickly received her first booking request from what she calls her first clients, the "OGs" ("it was pretty easy to get get on to it"; "I pretty quickly got a request uh from my uh uh first I call them the OGs, my first clients"). | G9: I pretty quickly got a request uh from my uh uh first I call them the OGs, my first clients | H9: =IF(COUNTIFS($D$2:D9,D9,$E$2:E9,E9,$A$2:A9,A9)=1,1,0) -> 0
A10: Andrew | B10: Pro | C10: Context and provider model | D10: business-model-fit | E10: fact | F10: Drew is a video editor by trade who has been doing Rover for about a year to a year and a half to supplement his income as film work slows down ("I've been doing Rover for a little bit over a year now. Uh just as a way to supplement my income because the industry is I think wrapping up uh in terms of film making"). | G10: I've been doing Rover for a little bit over a year now. Uh just as a way to supplement my income because the industry is I think wrapping up uh in terms of film making | H10: =IF(COUNTIFS($D$2:D10,D10,$E$2:E10,E10,$A$2:A10,A10)=1,1,0) -> 1
A11: Andrew | B11: Pro | C11: Context and provider model | D11: provider-background | E11: fact | F11: His services are boarding and doggy daycare, with boarding making up almost all of his business ("I do do boarding and um and doggy daycare, but it's it's almost 99%"). | G11: I do do boarding and um and doggy daycare, but it's it's almost 99% | H11: =IF(COUNTIFS($D$2:D11,D11,$E$2:E11,E11,$A$2:A11,A11)=1,1,0) -> 1
A12: Andrew | B12: Pro | C12: Context and provider model | D12: capacity-multi-pet-management | E12: fact | F12: He currently caps his capacity at two dogs at a time in addition to his own, occasionally taking a third for an emergency booking ("right now I take two dogs at a time"; "every once in a while, you know, if if there's a emergency booking, I'll take a third"). | G12: right now I take two dogs at a time | H12: =IF(COUNTIFS($D$2:D12,D12,$E$2:E12,E12,$A$2:A12,A12)=1,1,0) -> 1
A13: Andrew | B13: Pro | C13: Context and provider model | D13: provider-background | E13: fact | F13: In the month before the interview he was almost continuously booked, likely due to the start of summer travel season ("the last month I have been almost completely booked. I've had probably three or four days without at least one dog here"). | G13: the last month I have been almost completely booked. I've had probably three or four days without at least one dog here | H13: =IF(COUNTIFS($D$2:D13,D13,$E$2:E13,E13,$A$2:A13,A13)=1,1,0) -> 0
... A25: Anita | B25: Pro | C25: Context and provider model | D25: business-model-fit | E25: fact | F25: She describes her Rover income as essential to her finances, covering her rent and bills ("It's keeping me in this tiny apartment. It's helping me pay my bills. I absolutely need it."). | G25: It's keeping me in this tiny apartment. It's helping me pay my bills. I absolutely need it. | H25: =IF(COUNTIFS($D$2:D25,D25,$E$2:E25,E25,$A$2:A25,A25)=1,1,0) -> 1
A26: Anita | B26: Pro | C26: Context and provider model | D26: provider-background | E26: fact | F26: Her active client count fluctuates seasonally, from a high of six simultaneous households around one Christmas down to just one or two clients during a slow summer. | H26: =IF(COUNTIFS($D$2:D26,D26,$E$2:E26,E26,$A$2:A26,A26)=1,1,0) -> 0
A27: Anita | B27: Pro | C27: Context and provider model | D27: repeat-client-relationships | E27: fact | F27: One dog in her routine care, Boo, is technically a former client's dog who now lives with her full-time because his owner had a stroke and is currently in a care facility ("He's one of my dogs, but his mom had um strokes, so now I'm taking care of him full-time because she's in care."). | G27: He's one of my dogs, but his mom had um strokes, so now I'm taking care of him full-time because she's in care. | H27: =IF(COUNTIFS($D$2:D27,D27,$E$2:E27,E27,$A$2:A27,A27)=1,1,0) -> 1
A28: Becky | B28: Pro | C28: Context and provider model | D28: provider-background | E28: fact | F28: She says she is 36 years old ("I I'm still I'm 36"). | G28: I I'm still I'm 36 | H28: =IF(COUNTIFS($D$2:D28,D28,$E$2:E28,E28,$A$2:A28,A28)=1,1,0) -> 1
A29: Becky | B29: Pro | C29: Context and provider model | D29: provider-background | E29: fact | F29: She says she has been using Rover for about two years, though stated with hedging ("I've been using Rover for two years, I think."). | G29: I've been using Rover for two years, I think. | H29: =IF(COUNTIFS($D$2:D29,D29,$E$2:E29,E29,$A$2:A29,A29)=1,1,0) -> 0
A30: Becky | B30: Pro | C30: Context and provider model | D30: provider-background | E30: fact | F30: She immediately added further uncertainty about that length, saying it might actually be three years ("Maybe three, I don't know."). | G30: Maybe three, I don't know. | H30: =IF(COUNTIFS($D$2:D30,D30,$E$2:E30,E30,$A$2:A30,A30)=1,1,0) -> 0
A31: Becky | B31: Pro | C31: Context and provider model | D31: provider-background | E31: fact | F31: She says she is still working from home, a setup that has continued since COVID ("I'm still working from home after COVID time."). | G31: I'm still working from home after COVID time. | H31: =IF(COUNTIFS($D$2:D31,D31,$E$2:E31,E31,$A$2:A31,A31)=1,1,0) -> 0
A32: Becky | B32: Pro | C32: Context and provider model | D32: provider-background | E32: fact | F32: Before Rover, her pet-sitting experience was informal — watching her parents' or friends' dogs when they traveled ("I had done like my parents when they would go out of town I would watch their dogs or like their friends or something. Nothing too elaborate"). | G32: I had done like my parents when they would go out of town I would watch their dogs or like their friends or something. Nothing too elaborate | H32: =IF(COUNTIFS($D$2:D32,D32,$E$2:E32,E32,$A$2:A32,A32)=1,1,0) -> 0
A33: Becky | B33: Pro | C33: Context and provider model | D33: provider-background | E33: fact | F33: She says having a dog at her house, or being at someone else's, has become a frequent occurrence for her ("now I have a dog most mo more times than not I have a dog at my house or I'm at someone else."). | G33: now I have a dog most mo more times than not I have a dog at my house or I'm at someone else. | H33: =IF(COUNTIFS($D$2:D33,D33,$E$2:E33,E33,$A$2:A33,A33)=1,1,0) -> 0
A34: Becky | B34: Pro | C34: Context and provider model | D34: business-model-fit | E34: fact | F34: She says the concentration of her bookings in boarding is driven by demand rather than her own preference ("it's not because I have a preference. It's just because that's what gets booked more often."). | G34: it's not because I have a preference. It's just because that's what gets booked more often. | H34: =IF(COUNTIFS($D$2:D34,D34,$E$2:E34,E34,$A$2:A34,A34)=1,1,0) -> 1
A35: Becky | B35: Pro | C35: Context and provider model | D35: motivation-emotional-connection | E35: value-statement | F35: Asked directly about her own preference, though, she says she actually prefers overnight boarding and house-sitting over dog-walking because she doesn't have to travel back and forth as much ("it's actually much I prefer to have like the overnight sitting, the boarding or and I'm housesitting because then I don't have to drag so much. I'm just like wherever I am."). | G35: it's actually much I prefer to have like the overnight sitting, the boarding or and I'm housesitting because then I don't have to drag so much. I'm just like wherever I am. | H35: =IF(COUNTIFS($D$2:D35,D35,$E$2:E35,E35,$A$2:A35,A35)=1,1,0) -> 1
A36: Becky | B36: Pro | C36: Context and provider model | D36: provider-background | E36: fact | F36: She had expected significantly more dog-walking requests when she first signed up than she has actually received ("I thought when I first signed up, I was expecting a lot more dog walking."). | G36: I thought when I first signed up, I was expecting a lot more dog walking. | H36: =IF(COUNTIFS($D$2:D36,D36,$E$2:E36,E36,$A$2:A36,A36)=1,1,0) -> 0
A37: Becky | B37: Pro | C37: Context and provider model | D37: business-model-fit | E37: fact | F37: She says her boss was aware that she does dog sitting and that this wasn't a problem ("My boss um was aware of that I dog sitting. She's a big dog person, so it was not it wasn't at all."). | G37: My boss um was aware of that I dog sitting. She's a big dog person, so it was not it wasn't at all. | H37: =IF(COUNTIFS($D$2:D37,D37,$E$2:E37,E37,$A$2:A37,A37)=1,1,0) -> 0
A38: Becky | B38: Pro | C38: Context and provider model | D38: business-model-fit | E38: fact | F38: She describes fitting sitting into her work schedule as more a matter of working around her meetings than an actual problem, and says it didn't affect the quality of her work ("it was more like working around my meetings, but it didn't impact the quality of my work."). | G38: it was more like working around my meetings, but it didn't impact the quality of my work. | H38: =IF(COUNTIFS($D$2:D38,D38,$E$2:E38,E38,$A$2:A38,A38)=1,1,0) -> 0
... A67: Erika | B67: Pro | C67: Context and provider model | D67: provider-background | E67: fact | F67: She now has a baby, which is part of her current household context ("I also have a baby"). | G67: I also have a baby | H67: =IF(COUNTIFS($D$2:D67,D67,$E$2:E67,E67,$A$2:A67,A67)=1,1,0) -> 0
A68: Erika | B68: Pro | C68: Context and provider model | D68: client-dog-screening-criteria | E68: fact | F68: Her living situation also shapes which bookings she can take: she rents her home under a landlord agreement restricting her to small- or medium-sized pets (see Evaluation and meet-and-greet for the full detail and quote). | H68: =IF(COUNTIFS($D$2:D68,D68,$E$2:E68,E68,$A$2:A68,A68)=1,1,0) -> 1
A69: Erika | B69: Pro | C69: Context and provider model | D69: repeat-client-relationships | E69: fact | F69: She has a base of regular clients, though she says the balance has recently shifted toward new clients ("I have a couple of regular clients"). | G69: I have a couple of regular clients | H69: =IF(COUNTIFS($D$2:D69,D69,$E$2:E69,E69,$A$2:A69,A69)=1,1,0) -> 1
A70: Erika | B70: Pro | C70: Context and provider model | D70: provider-background | E70: fact | F70: Her Rover profile also has drop-in visits and daycare activated, but boarding -- pets staying with her for scheduled days or nights -- is the service type she says she has done most ("the most common one is the boarding one. That is the one that they spend some days or some nights here as like schedule times... so that's the most common and to be honest that's the one that I mostly have done so far"). | G70: the most common one is the boarding one. That is the one that they spend some days or some nights here as like schedule times... so that's the most common and to be honest that's the one that I mostly have done so far | H70: =IF(COUNTIFS($D$2:D70,D70,$E$2:E70,E70,$A$2:A70,A70)=1,1,0) -> 0
A71: Erika | B71: Pro | C71: Context and provider model | D71: client-acquisition-discovery | E71: fact | F71: In roughly the three to four months before the interview she noticed a sharp rise in new clients on top of her existing regulars ("I've noticed that in this last I don't know like maybe three" ... "to four months I've gotten lots of new" [pets]). | G71: to four months I've gotten lots of new | H71: =IF(COUNTIFS($D$2:D71,D71,$E$2:E71,E71,$A$2:A71,A71)=1,1,0) -> 1
A72: Kristin | B72: Pro | C72: Context and provider model | D72: business-model-fit | E72: fact | F72: She did Rover full-time until April, then returned to her full-time day job and is now doing Rover part-time again ("I had been doing Rover full-time. um up until April."). | G72: I had been doing Rover full-time. um up until April. | H72: =IF(COUNTIFS($D$2:D72,D72,$E$2:E72,E72,$A$2:A72,A72)=1,1,0) -> 1
A73: Kristin | B73: Pro | C73: Context and provider model | D73: provider-background | E73: fact | F73: Her full-time day job is on the administrative side of the emergency field, which she describes as less stressful than the facility-based role she previously had in the same field ("it's on the admin side and I don't deal with it in the facility"). | G73: it's on the admin side and I don't deal with it in the facility | H73: =IF(COUNTIFS($D$2:D73,D73,$E$2:E73,E73,$A$2:A73,A73)=1,1,0) -> 1
A74: Kristin | B74: Pro | C74: Context and provider model | D74: business-model-fit | E74: fact | F74: Roughly 90% of her pet-sitting income comes through Rover, with the rest from private clients found through word of mouth, Facebook, and NextDoor ("90% of my petsitting income off Rover."). | G74: 90% of my petsitting income off Rover. | H74: =IF(COUNTIFS($D$2:D74,D74,$E$2:E74,E74,$A$2:A74,A74)=1,1,0) -> 0
A75: Kristin | B75: Pro | C75: Context and provider model | D75: provider-background | E75: fact | F75: Her active client base includes "approximately six or seven like weekly clients" plus an estimated 60-100 intermittent yearly clients who book around vacations. | G75: approximately six or seven like weekly clients | H75: =IF(COUNTIFS($D$2:D75,D75,$E$2:E75,E75,$A$2:A75,A75)=1,1,0) -> 0
A76: Kristin | B76: Pro | C76: Context and provider model | D76: provider-background | E76: fact | F76: She is engaged and has her own dogs at home, which come up as part of her daily life during the interview itself ("my dog and dogs are going to start barking and my fiance's getting ready for work."). | G76: my dog and dogs are going to start barking and my fiance's getting ready for work. | H76: =IF(COUNTIFS($D$2:D76,D76,$E$2:E76,E76,$A$2:A76,A76)=1,1,0) -> 0
A77: Kristin | B77: Pro | C77: Context and provider model | D77: provider-background | E77: fact | F77: She recently had surgery, which affected her capacity to work ("I've just recently had surgery"). | G77: I've just recently had surgery | H77: =IF(COUNTIFS($D$2:D77,D77,$E$2:E77,E77,$A$2:A77,A77)=1,1,0) -> 0
A78: Kristin | B78: Pro | C78: Context and provider model | D78: motivation-emotional-connection | E78: value-statement | F78: She describes herself as a very busy person who likes it that way, juggling dog walks and drop-ins around her full-time job plus overnight house-sits ("Yeah. Yeah. I'm a very busy person. I like being busy."). | G78: Yeah. Yeah. I'm a very busy person. I like being busy. | H78: =IF(COUNTIFS($D$2:D78,D78,$E$2:E78,E78,$A$2:A78,A78)=1,1,0) -> 1
A79: Naomi | B79: Pro | C79: Context and provider model | D79: provider-background | E79: fact | F79: She is a Pro-segment Rover provider based in the Bronx, New York City, running her boarding operation out of a home with a large yard that she bought after leaving the tech industry ("I bought a home in the Bronx and so the home has a large yard"). | G79: I bought a home in the Bronx and so the home has a large yard | H79: =IF(COUNTIFS($D$2:D79,D79,$E$2:E79,E79,$A$2:A79,A79)=1,1,0) -> 1
...

Sheet Friction-Need Frequency
A1: Theme | B1: Type | C1: Distinct providers (of 14 Pro) | D1: Which providers | E1: Representative observation | F1: Representative quote
A2: messaging-platform-mechanics | B2: friction | C2: =SUMIFS('Raw Atomic Data (Pro)'!$H$2:$H$978,'Raw Atomic Data (Pro)'!$D$2:$D$978,A2,'Raw Atomic Data (Pro)'!$E$2:$E$978,B2) -> 9 | D2: Ami, Andrew, Anita, Ashley P., Becky, Colin, Erika, Naomi, Tifany | E2: [Andrew] He finds it a little annoying when the app sends an automated/generated first message on a client's behalf, because the client doesn't always know what it says ("I think sometime it does the automated like the generated message like hello I'd like to I was like that's a little annoying because like they don't really know what it says"). | F2: I think sometime it does the automated like the generated message like hello I'd like to I was like that's a little annoying because like they don't really know what it says
A3: calendar-scheduling-tools | B3: need | C3: =SUMIFS('Raw Atomic Data (Pro)'!$H$2:$H$978,'Raw Atomic Data (Pro)'!$D$2:$D$978,A3,'Raw Atomic Data (Pro)'!$E$2:$E$978,B3) -> 7 | D3: Ami, Anita, Becky, Dawn, Naomi, Tianrui, Tifany | E3: [Ami] She would like Rover's calendar to sync or link directly with her personal Google Calendar so she doesn't have to manually type in every appointment ("That would be nice if it was linked because then I wouldn't have to physically, you know, write or, you know, type in five or six different appointments"). | F3: That would be nice if it was linked because then I wouldn't have to physically, you know, write or, you know, type in five or six different appointments
A4: calendar-scheduling-tools | B4: workaround | C4: =SUMIFS('Raw Atomic Data (Pro)'!$H$2:$H$978,'Raw Atomic Data (Pro)'!$D$2:$D$978,A4,'Raw Atomic Data (Pro)'!$E$2:$E$978,B4) -> 6 | D4: Anita, Ashley P., Colin, Kristin, Naomi, Tifany | E4: [Anita] She also uses Google's alarm/clock feature to make sure she gets to each appointment on time ("Google alarms, the clock to set off so I know remember to go to each next appointment"). | F4: Google alarms, the clock to set off so I know remember to go to each next appointment
A5: calendar-scheduling-tools | B5: friction | C5: =SUMIFS('Raw Atomic Data (Pro)'!$H$2:$H$978,'Raw Atomic Data (Pro)'!$D$2:$D$978,A5,'Raw Atomic Data (Pro)'!$E$2:$E$978,B5) -> 5 | D5: Becky, Kristin, Naomi, Tianrui, Tifany | E5: [Becky] She describes a past bug, lasting multiple months, where the date entered for scheduling a meet and greet in the chat would shift to the day before every time; she believes this has since been fixed ("there was a long period of time like multiple months I think where the date would always you would put in the date but it would like change to the day before every time you put the date and so it would always be wrong. Um, and that was very annoying. I think they fixed it now."). | F5: there was a long period of time like multiple months I think where the date would always you would put in the date but it would like change to the day before every time you put the date and so it would always be wrong. Um, and that was very annoying. I think they fixed it now.
A6: care-instructions-handoff | B6: workaround | C6: =SUMIFS('Raw Atomic Data (Pro)'!$H$2:$H$978,'Raw Atomic Data (Pro)'!$D$2:$D$978,A6,'Raw Atomic Data (Pro)'!$E$2:$E$978,B6) -> 5 | D6: Ami, Andrew, Anita, Bruna, Kristin | E6: [Ami] She keeps a physical "blue notebook" in which she writes down details from every meet-and-greet, including addresses, house codes, feeding schedules, and medication, while the owner talks and as she walks around the house ("Every time I get do a meet and greet, I write everything down in that" and "I know addresses um I know house codes, you know, um I know feeding schedules, uh medication, all that"). | F6: I know addresses um I know house codes, you know, um I know feeding schedules, uh medication, all that
A7: messaging-platform-mechanics | B7: need | C7: =SUMIFS('Raw Atomic Data (Pro)'!$H$2:$H$978,'Raw Atomic Data (Pro)'!$D$2:$D$978,A7,'Raw Atomic Data (Pro)'!$E$2:$E$978,B7) -> 5 | D7: Ashley P., Erika, Naomi, Tianrui, Tifany | E7: [Tianrui] TR wishes Rover's text-message notifications could display photos and videos directly, since clients who haven't downloaded the Rover app can't otherwise see media without logging into the app ("some clients just don't download the Rover app at all and they just only rely on the chats... if they can like also make the photos and a video show up on the text message interface going to be better"). | F7: if they can like also make the photos and a video show up on the text message interface going to be better
A8: payout-timing-tracking | B8: need | C8: =SUMIFS('Raw Atomic Data (Pro)'!$H$2:$H$978,'Raw Atomic Data (Pro)'!$D$2:$D$978,A8,'Raw Atomic Data (Pro)'!$E$2:$E$978,B8) -> 5 | D8: Andrew, Ashley P., Naomi, Tianrui, Tifany | E8: [Andrew] He would prefer a payout breakdown by specific date and booking rather than one lump total ("I would find that a little more useful to know to to know like not just how much is coming, but specifically when and for what"). | F8: I would find that a little more useful to know to to know like not just how much is coming, but specifically when and for what
A9: business-model-fit | B9: friction | C9: =SUMIFS('Raw Atomic Data (Pro)'!$H$2:$H$978,'Raw Atomic Data (Pro)'!$D$2:$D$978,A9,'Raw Atomic Data (Pro)'!$E$2:$E$978,B9) -> 4 | D9: Anita, Ashley P., Becky, Erika | E9: [Becky] She says the one real challenge was finding a good time to walk a dog when her work meetings started early (around 6:00 a.m.) and were busy that morning ("the only challenge is really like finding a good time to go on a walk. If I have meetings starting at 6:00 and my meetings were very busy in the morning, then like getting a good time to go on a walk was a little bit tricky."). | F9: the only challenge is really like finding a good time to go on a walk. If I have meetings starting at 6:00 and my meetings were very busy in the morning, then like getting a good time to go on a walk was a little bit tricky.
A10: safety-risk-incidents | B10: friction | C10: =SUMIFS('Raw Atomic Data (Pro)'!$H$2:$H$978,'Raw Atomic Data (Pro)'!$D$2:$D$978,A10,'Raw Atomic Data (Pro)'!$E$2:$E$978,B10) -> 4 | D10: Anita, Bruna, Naomi, Tifany | E10: [Anita] She described one meet-and-greet where an older, unsocialized dog attacked her, and she believed the owner was trying to get rid of the dog rather than find genuine care ("The dog was older and aggressive and as soon as I got there, he attacked me"; "it was a bad owner. They were trying to dump the dog"). | F10: it was a bad owner. They were trying to dump the dog
A11: care-instructions-handoff | B11: need | C11: =SUMIFS('Raw Atomic Data (Pro)'!$H$2:$H$978,'Raw Atomic Data (Pro)'!$D$2:$D$978,A11,'Raw Atomic Data (Pro)'!$E$2:$E$978,B11) -> 4 | D11: Andrew, Anita, Ashley P., Becky | E11: [Andrew] He is unsure whether Rover has a private notes feature for sitters to keep track of client/dog details themselves, and thinks it would be useful if it existed ("I don't know if there is a note feature"). | F11: I don't know if there is a note feature
A12: off-platform-communication-channels | B12: workaround | C12: =SUMIFS('Raw Atomic Data (Pro)'!$H$2:$H$978,'Raw Atomic Data (Pro)'!$D$2:$D$978,A12,'Raw Atomic Data (Pro)'!$E$2:$E$978,B12) -> 4 | D12: Anita, Colin, Erika, Kristin | E12: [Anita] She has had clients text her at very late hours expecting round-the-clock availability, but she does not respond until the next morning rather than feeling obligated to reply immediately ("I will get text messages at 12 and midnight. I'm like, I won't see them till the next morning"). | F12: I will get text messages at 12 and midnight. I'm like, I won't see them till the next morning
A13: messaging-platform-mechanics | B13: workaround | C13: =SUMIFS('Raw Atomic Data (Pro)'!$H$2:$H$978,'Raw Atomic Data (Pro)'!$D$2:$D$978,A13,'Raw Atomic Data (Pro)'!$E$2:$E$978,B13) -> 4 | D13: Ashley P., Becky, Naomi, Shania | E13: [Becky] Her general approach is to redirect Rover messages to her phone's regular text app rather than opening the Rover app, since it's easier than navigating the app's UI ("it's just easier just comes up as a text message rather than me having to open app and then navigate their UI."). | F13: it's just easier just comes up as a text message rather than me having to open app and then navigate their UI.
... A63: tipping | B63: friction | C63: =SUMIFS('Raw Atomic Data (Pro)'!$H$2:$H$978,'Raw Atomic Data (Pro)'!$D$2:$D$978,A63,'Raw Atomic Data (Pro)'!$E$2:$E$978,B63) -> 1 | D63: Ashley P. | E63: [Ashley P.] She says clients often tip her, but the tip option only becomes available after the client submits a full review first, which she believes reduces how often people tip, even though she also understands the design likely helps ensure more consistent reviews ("The problem is is they have to leave a full review basically to get to the tip part... I think that there would be the potential for more tips if it wasn't um like dug into that section, but also I understand it in a way because it it gets people to review which may not happen as consistently if it wasn't in that same area."). | F63: The problem is is they have to leave a full review basically to get to the tip part
A65: Note: counts are distinct providers who raised this theme/type at least once, not row counts. A theme with a low count may still be a real issue for that provider -- it just isn't (yet) widely shared across the Pro segment.

Sheet Leakage - By Participant
A1: Participant | B1: Status | C1: Who initiates | D1: Reason given | E1: Notes (grounded in transcript)
A2: Ami | B2: Some leakage -- 2 documented cases | C2: Client | D2: Not stated | E2: Does not proactively suggest moving off Rover; agrees if the client asks.
A3: Andrew | B3: No leakage | C3: N/A | D3: N/A | E3: Says everything is on Rover. Separately explains why he stays: Rover handles communication/scheduling/liability, and he dislikes admin paperwork and self-marketing alternatives (flyers, Nextdoor).
A4: Anita | B4: Some leakage -- owner-initiated fee-avoidance attempts | C4: Client / owner | D4: Avoid Rover's fees | E4: Frames it as outside her control ('that's up to the owner'). Says she'd only look for another platform if Rover itself shut down.
A5: Ashley P. | B5: Some leakage -- ~3 clients over time | C5: Client | D5: Avoid fees that 'go nowhere'; client still pays her the same amount | E5: Says it's always the client who raises it, never her; keeps almost all clients on Rover.
A6: Becky | B6: Recurring leakage -- multiple clients taken offline | C6: Mixed (sometimes client asks directly, sometimes mutual once familiar) | D6: Not explicitly stated beyond avoiding Rover / comfort with familiarity | E6: Acknowledges this is against Rover's rules. Charges offline clients less than the Rover listing price, splitting the difference with her own take-home.
A7: Bruna | B7: No leakage | C7: N/A | D7: N/A | E7: Rover is her only platform; gets referrals through a private trainer network but books through Rover.
A8: Colin | B8: No leakage | C8: N/A | D8: N/A | E8: Everything is done through the app.
A9: Dawn | B9: Unclear / unconfirmed | C9: N/A | D9: N/A | E9: Audio was garbled at this question in the transcript; cannot be confirmed.
A10: Erika | B10: No leakage (stated as a general rule) | C10: N/A | D10: N/A | E10: Says she never books new clients outside the app.
A11: Kristin | B11: Partial leakage -- about 10% of clients | C11: Client | D11: Preference for other channels (not fee-avoidance) -- mostly elderly clients defaulting to NextDoor, Facebook, or phone | E11: When a client reaches out off-platform first, she redirects them back to her Rover profile.
A12: Naomi | B12: No stated instance in this theme | C12: N/A | D12: N/A | E12: Runs a separate private client base in parallel (Google Calendar, spreadsheets, a payment processor), but this is not documented as Rover clients converting off-platform.
... A15: Tifany | B15: Declined -- provider deliberately keeps clients on Rover | C15: Provider (deliberate policy) | D15: N/A (provider-side reason, not a client ask) | E15: Says she's afraid of losing her standing on Rover if she moves clients off; leaves the choice to the client but doesn't encourage it.
A18: Status bucket counts (of 14 Pro providers):
A19: No leakage | B19: =COUNTIF($B$2:$B$15,"*No leakage*") -> 5
A20: Some leakage | B20: =COUNTIF($B$2:$B$15,"*Some leakage*") -> 3
A21: Partial leakage | B21: =COUNTIF($B$2:$B$15,"*Partial leakage*") -> 1
A22: Recurring leakage | B22: =COUNTIF($B$2:$B$15,"*Recurring leakage*") -> 1
A23: Declined | B23: =COUNTIF($B$2:$B$15,"*Declined*") -> 2
A24: Unclear | B24: =COUNTIF($B$2:$B$15,"*Unclear*") -> 1
A25: No stated instance | B25: =COUNTIF($B$2:$B$15,"*No stated instance*") -> 1
A26: Total (should equal 14) | B26: =SUM(B19:B25) -> 14

Sheet Leakage - Raw Evidence
A1: Participant | B1: Type | C1: Category | D1: Observation | E1: Quote
A2: Tianrui | B2: fact | C2: Context and provider model | D2: TR has never taken on private, off-platform clients — all clients come through Rover ("I don't do privately"). | E2: I don't do privately
A3: Kristin | B3: fact | C3: Client acquisition | D3: Even when a client first reaches out off-platform, she directs them back to her Rover profile to see her availability, pricing, and reviews ("here's my Rover app if you need to see my" availability, pricing, reviews). | E3: here's my Rover app if you need to see my
A4: Becky | B4: fact | C4: Payments and earnings | D4: When she takes a repeat client's booking offline, she says she charges them less than Rover would, splitting the difference between her Rover take-home and the full Rover listing price so the client pays less while she keeps more of the money ("I typically charge less than what Rover would charge, but I like split the difference between my take-home from Rover and Got over the booking the listing price. So they pay less and I get to take home"). | E4: I typically charge less than what Rover would charge, but I like split the difference between my take-home from Rover and Got over the booking the listing price. So they pay less and I get to take home
A5: Ami | B5: fact | C5: Cross-platform behavior | D5: Two of her Rover clients proposed moving their arrangement off-platform after first contacting her through Rover, and she went along with it ("We started with Rover and then they just said, 'Hey, let's just do this, you know, let's let's just do this outside of Rover.'" and "that's happened in I want to say maybe two cases"). | E5: We started with Rover and then they just said, 'Hey, let's just do this, you know, let's let's just do this outside of Rover.'
A6: Ami | B6: fact | C6: Cross-platform behavior | D6: She doesn't proactively suggest moving a relationship off Rover herself, but will agree if the client requests it ("I usually I don't say anything to the person. I if they say something to me like I'd rather do this outside of Rover then I'll be like okay we we can do that"). | E6: I usually I don't say anything to the person. I if they say something to me like I'd rather do this outside of Rover then I'll be like okay we we can do that
A7: Andrew | B7: fact | C7: Cross-platform behavior | D7: He has no off-platform clients at all; everything runs through Rover ("No, it's all on rover"). | E7: No, it's all on rover
A8: Andrew | B8: value-statement | C8: Cross-platform behavior | D8: He considered but rejected doing pet sitting independently, because Rover already handles communication, scheduling, and provides a sense of security/liability that he'd otherwise have to arrange himself ("there's just so many things I feel like Rover takes care of like a lot of little especially communication scheduling uh and just providing a sense of security and liability for both parties"). | E8: there's just so many things I feel like Rover takes care of like a lot of little especially communication scheduling uh and just providing a sense of security and liability for both parties
A9: Andrew | B9: value-statement | C9: Cross-platform behavior | D9: He compares Rover favorably to alternative self-marketing channels he considered unappealing, like flyers at the dog park or figuring out Nextdoor ("I'm like putting up flyers at the dog park. I'm trying to figure out how Next Door works as a platform. Uh and none of that's very appealing to me"). | E9: I'm like putting up flyers at the dog park. I'm trying to figure out how Next Door works as a platform. Uh and none of that's very appealing to me
A10: Andrew | B10: value-statement | C10: Cross-platform behavior | D10: He also cites avoiding administrative paperwork as a reason for staying on Rover rather than operating independently, describing himself as bad at it ("I'm also terrible at paperwork. It was like if I could just force that all off on somebody"). | E10: I'm also terrible at paperwork. It was like if I could just force that all off on somebody
A11: Anita | B11: fact | C11: Cross-platform behavior | D11: Clients have tried to move some bookings off the Rover platform directly to avoid Rover's fees; she confirms this has happened, and frames it as the owner's decision rather than something within her control ("it has happened only because the owners don't want to pay" the fees; "that's not in my control, you know, that's something it's up to the owner"). | E11: it has happened only because the owners don't want to pay
A12: Becky | B12: fact | C12: Cross-platform behavior | D12: Once she and a client are friendly and both feel comfortable, she says they can take the arrangement offline ("once we're friends, um if if everyone feels good about taking it offline, we can take it offline."). | E12: once we're friends, um if if everyone feels good about taking it offline, we can take it offline.
... A30: Ashley P. | B30: fact | C30: Cross-platform behavior | D30: In those cases, the pet parent frames it as wanting to stop paying fees that "go nowhere" while still paying her the same amount, which she describes as a "win-win" ("It's always the pet parent that's like, 'Hey,... I don't want to pay these fees that are going nowhere, and I want you to get paid the same amount.' So, it's like a win-win in those scenarios."). | E30: It's always the pet parent that's like

Sheet Theme Legend
A1: Theme | B1: Definition
A2: provider-background | B2: Background facts about who the provider is - age, family, living situation, other job, own pets - not directly about Rover.
A3: motivation-emotional-connection | B3: Why the provider does pet sitting and the personal/emotional value they get from being around animals.
A4: business-model-fit | B4: How pet sitting fits alongside the provider's other income, job, and life schedule (side income, full-time/part-time framing, flexibility).
A5: onboarding-signup-process | B5: Getting set up on Rover initially - background check, account verification, first approval, choosing Rover over alternatives.
A6: client-acquisition-discovery | B6: How new clients first find and contact the sitter, and what the sitter does to attract them.
A7: search-ranking-visibility | B7: Rover's search-ranking/algorithm and how it affects a sitter's visibility, especially for new or lower-ranked sitters.
A8: meet-and-greet-process | B8: How meet-and-greets are conducted - logistics, format, purpose, in-person vs. video.
A9: client-dog-screening-criteria | B9: The sitter's criteria and non-negotiables for accepting or declining a specific dog or client (aggression, size, breed, behavior, distance).
A10: safety-risk-incidents | B10: Physical-safety concerns and incidents involving the sitter, a dog, or an owner, and personal-safety precautions.
A11: calendar-scheduling-tools | B11: Tools and behavior for tracking availability and bookings - Rover's calendar, Google Calendar sync, calendar bugs.
A12: booking-confirmation-mechanics | B12: The mechanics of how a request becomes a confirmed (or cancelled) booking - blocking dates, mutual confirmation, cancellation rules.
... A31: daily-care-tasks | B31: Neutral facts about the concrete tasks performed during a sit - feeding, walking, medicating, cleaning.

Sheet Journey Map (Pro)
A1: Stage | B1: What this stage covers | C1: Off-platform leakage note for this stage | J1: Helper: Participant | K1: Helper: Category | L1: Helper: Theme | M1: Helper: Type | N1: Helper: Is friction/need/workaround | O1: Helper: 1st occurrence of Category+Theme+Type+Participant | P1: Helper: 1st occurrence of Theme+Participant (FNW only) | Q1: Helper: 1st occurrence of Theme+Category (FNW only) | R1: Helper: 1st occurrence of Category+Theme+Participant (FNW only) | S1: Helper: Is stage category (excludes Context/Motivation)
A2: Client acquisition | B2: How clients first find and contact the provider, before any screening or decision happens. | C2: One off-platform-clients-leakage row is tagged in this stage: Kristin describes redirecting off-platform inquiries back to her Rover profile ("here's my Rover app if you need to see my [availability, pricing, and reviews]") rather than losing the lead off-platform. This is a retention behavior at the discovery stage, not an instance of a client or booking actually leaving Rover. | J2: ='Raw Atomic Data (Pro)'!A2 -> Ami | K2: ='Raw Atomic Data (Pro)'!C2 -> Context and provider model | L2: ='Raw Atomic Data (Pro)'!D2 -> provider-background | M2: ='Raw Atomic Data (Pro)'!E2 -> fact | N2: =IF(OR(M2="friction",M2="need",M2="workaround"),1,0) -> 0 | O2: =IF(COUNTIFS($K$2:K2,K2,$L$2:L2,L2,$M$2:M2,M2,$J$2:J2,J2)=1,1,0) -> 1 | P2: =IF(AND(N2=1,S2=1,COUNTIFS($L$2:L2,L2,$J$2:J2,J2,$N$2:N2,1,$S$2:S2,1)=1),1,0) -> 0 | Q2: =IF(AND(N2=1,S2=1,COUNTIFS($L$2:L2,L2,$K$2:K2,K2,$N$2:N2,1,$S$2:S2,1)=1),1,0) -> 0 | R2: =IF(AND(N2=1,COUNTIFS($K$2:K2,K2,$L$2:L2,L2,$J$2:J2,J2,$N$2:N2,1)=1),1,0) -> 0 | S2: =IF(AND(K2<>"Context and provider model",K2<>"Motivation"),1,0) -> 0
A3: Evaluation and meet-and-greet | B3: The screening/decision moment -- how the provider decides whether to accept a specific client or pet, meet-and-greet behavior. | C3: No off-platform-clients-leakage rows are tagged in this stage. | J3: ='Raw Atomic Data (Pro)'!A3 -> Ami | K3: ='Raw Atomic Data (Pro)'!C3 -> Context and provider model | L3: ='Raw Atomic Data (Pro)'!D3 -> provider-background | M3: ='Raw Atomic Data (Pro)'!E3 -> fact | N3: =IF(OR(M3="friction",M3="need",M3="workaround"),1,0) -> 0 | O3: =IF(COUNTIFS($K$2:K3,K3,$L$2:L3,L3,$M$2:M3,M3,$J$2:J3,J3)=1,1,0) -> 0 | P3: =IF(AND(N3=1,S3=1,COUNTIFS($L$2:L3,L3,$J$2:J3,J3,$N$2:N3,1,$S$2:S3,1)=1),1,0) -> 0 | Q3: =IF(AND(N3=1,S3=1,COUNTIFS($L$2:L3,L3,$K$2:K3,K3,$N$2:N3,1,$S$2:S3,1)=1),1,0) -> 0 | R3: =IF(AND(N3=1,COUNTIFS($K$2:K3,K3,$L$2:L3,L3,$J$2:J3,J3,$N$2:N3,1)=1),1,0) -> 0 | S3: =IF(AND(K3<>"Context and provider model",K3<>"Motivation"),1,0) -> 0
A4: Booking and availability | B4: Scheduling mechanics once a booking is being arranged: calendar management, confirming dates, cancellations. | C4: No off-platform-clients-leakage rows are tagged in this stage. | J4: ='Raw Atomic Data (Pro)'!A4 -> Ami | K4: ='Raw Atomic Data (Pro)'!C4 -> Context and provider model | L4: ='Raw Atomic Data (Pro)'!D4 -> provider-background | M4: ='Raw Atomic Data (Pro)'!E4 -> fact | N4: =IF(OR(M4="friction",M4="need",M4="workaround"),1,0) -> 0 | O4: =IF(COUNTIFS($K$2:K4,K4,$L$2:L4,L4,$M$2:M4,M4,$J$2:J4,J4)=1,1,0) -> 0 | P4: =IF(AND(N4=1,S4=1,COUNTIFS($L$2:L4,L4,$J$2:J4,J4,$N$2:N4,1,$S$2:S4,1)=1),1,0) -> 0 | Q4: =IF(AND(N4=1,S4=1,COUNTIFS($L$2:L4,L4,$K$2:K4,K4,$N$2:N4,1,$S$2:S4,1)=1),1,0) -> 0 | R4: =IF(AND(N4=1,COUNTIFS($K$2:K4,K4,$L$2:L4,L4,$J$2:J4,J4,$N$2:N4,1)=1),1,0) -> 0 | S4: =IF(AND(K4<>"Context and provider model",K4<>"Motivation"),1,0) -> 0
A5: Sitting preparation | B5: Between confirmed booking and the sit starting: care instructions, medication/emergency info, keys/access. | C5: No off-platform-clients-leakage rows are tagged in this stage. | J5: ='Raw Atomic Data (Pro)'!A5 -> Ami | K5: ='Raw Atomic Data (Pro)'!C5 -> Context and provider model | L5: ='Raw Atomic Data (Pro)'!D5 -> business-model-fit | M5: ='Raw Atomic Data (Pro)'!E5 -> fact | N5: =IF(OR(M5="friction",M5="need",M5="workaround"),1,0) -> 0 | O5: =IF(COUNTIFS($K$2:K5,K5,$L$2:L5,L5,$M$2:M5,M5,$J$2:J5,J5)=1,1,0) -> 1 | P5: =IF(AND(N5=1,S5=1,COUNTIFS($L$2:L5,L5,$J$2:J5,J5,$N$2:N5,1,$S$2:S5,1)=1),1,0) -> 0 | Q5: =IF(AND(N5=1,S5=1,COUNTIFS($L$2:L5,L5,$K$2:K5,K5,$N$2:N5,1,$S$2:S5,1)=1),1,0) -> 0 | R5: =IF(AND(N5=1,COUNTIFS($K$2:K5,K5,$L$2:L5,L5,$J$2:J5,J5,$N$2:N5,1)=1),1,0) -> 0 | S5: =IF(AND(K5<>"Context and provider model",K5<>"Motivation"),1,0) -> 0
A6: Service delivery | B6: What the provider actually does during the sit: daily care tasks, on-site issue handling. | C6: No off-platform-clients-leakage rows are tagged in this stage. | J6: ='Raw Atomic Data (Pro)'!A6 -> Ami | K6: ='Raw Atomic Data (Pro)'!C6 -> Context and provider model | L6: ='Raw Atomic Data (Pro)'!D6 -> provider-background | M6: ='Raw Atomic Data (Pro)'!E6 -> fact | N6: =IF(OR(M6="friction",M6="need",M6="workaround"),1,0) -> 0 | O6: =IF(COUNTIFS($K$2:K6,K6,$L$2:L6,L6,$M$2:M6,M6,$J$2:J6,J6)=1,1,0) -> 0 | P6: =IF(AND(N6=1,S6=1,COUNTIFS($L$2:L6,L6,$J$2:J6,J6,$N$2:N6,1,$S$2:S6,1)=1),1,0) -> 0 | Q6: =IF(AND(N6=1,S6=1,COUNTIFS($L$2:L6,L6,$K$2:K6,K6,$N$2:N6,1,$S$2:S6,1)=1),1,0) -> 0 | R6: =IF(AND(N6=1,COUNTIFS($K$2:K6,K6,$L$2:L6,L6,$J$2:J6,J6,$N$2:N6,1)=1),1,0) -> 0 | S6: =IF(AND(K6<>"Context and provider model",K6<>"Motivation"),1,0) -> 0
A7: Client communication | B7: How communication style, frequency, or tone changes over a relationship or a stay's length. | C7: No off-platform-clients-leakage rows are tagged in this stage. Note this is distinct from the off-platform-communication-channels theme (channel choice -- texting/WhatsApp/etc. -- not client or booking migration), which is heavily tagged here (see 'Frictions / Needs / Workarounds by Stage' table below); channel choice and client leakage are separate coded themes and are not combined in this note. | J7: ='Raw Atomic Data (Pro)'!A7 -> Ami | K7: ='Raw Atomic Data (Pro)'!C7 -> Context and provider model | L7: ='Raw Atomic Data (Pro)'!D7 -> business-model-fit | M7: ='Raw Atomic Data (Pro)'!E7 -> value-statement | N7: =IF(OR(M7="friction",M7="need",M7="workaround"),1,0) -> 0 | O7: =IF(COUNTIFS($K$2:K7,K7,$L$2:L7,L7,$M$2:M7,M7,$J$2:J7,J7)=1,1,0) -> 1 | P7: =IF(AND(N7=1,S7=1,COUNTIFS($L$2:L7,L7,$J$2:J7,J7,$N$2:N7,1,$S$2:S7,1)=1),1,0) -> 0 | Q7: =IF(AND(N7=1,S7=1,COUNTIFS($L$2:L7,L7,$K$2:K7,K7,$N$2:N7,1,$S$2:S7,1)=1),1,0) -> 0 | R7: =IF(AND(N7=1,COUNTIFS($K$2:K7,K7,$L$2:L7,L7,$J$2:J7,J7,$N$2:N7,1)=1),1,0) -> 0 | S7: =IF(AND(K7<>"Context and provider model",K7<>"Motivation"),1,0) -> 0
A8: Completion and feedback | B8: What happens once a sit ends: payment trigger/confirmation, reviews, follow-up, relationship continuation. | C8: No off-platform-clients-leakage rows are tagged in this stage. | J8: ='Raw Atomic Data (Pro)'!A8 -> Ami | K8: ='Raw Atomic Data (Pro)'!C8 -> Context and provider model | L8: ='Raw Atomic Data (Pro)'!D8 -> onboarding-signup-process | M8: ='Raw Atomic Data (Pro)'!E8 -> value-statement | N8: =IF(OR(M8="friction",M8="need",M8="workaround"),1,0) -> 0 | O8: =IF(COUNTIFS($K$2:K8,K8,$L$2:L8,L8,$M$2:M8,M8,$J$2:J8,J8)=1,1,0) -> 1 | P8: =IF(AND(N8=1,S8=1,COUNTIFS($L$2:L8,L8,$J$2:J8,J8,$N$2:N8,1,$S$2:S8,1)=1),1,0) -> 0 | Q8: =IF(AND(N8=1,S8=1,COUNTIFS($L$2:L8,L8,$K$2:K8,K8,$N$2:N8,1,$S$2:S8,1)=1),1,0) -> 0 | R8: =IF(AND(N8=1,COUNTIFS($K$2:K8,K8,$L$2:L8,L8,$J$2:J8,J8,$N$2:N8,1)=1),1,0) -> 0 | S8: =IF(AND(K8<>"Context and provider model",K8<>"Motivation"),1,0) -> 0
A9: Payments and earnings | B9: Pricing, fees, tipping, income tracking, Rover vs. off-platform pricing. | C9: One off-platform-clients-leakage row is tagged in this stage: Becky describes charging clients she has taken offline less than the full Rover listing price, splitting the difference between that and her own Rover take-home ("I typically charge less than what Rover would charge, but I like split the difference between my take-home from Rover and [the full] booking [price]"). This is about the pricing mechanics of an already-leaked relationship, not the leakage trigger itself. | J9: ='Raw Atomic Data (Pro)'!A9 -> Ami | K9: ='Raw Atomic Data (Pro)'!C9 -> Context and provider model | L9: ='Raw Atomic Data (Pro)'!D9 -> onboarding-signup-process | M9: ='Raw Atomic Data (Pro)'!E9 -> value-statement | N9: =IF(OR(M9="friction",M9="need",M9="workaround"),1,0) -> 0 | O9: =IF(COUNTIFS($K$2:K9,K9,$L$2:L9,L9,$M$2:M9,M9,$J$2:J9,J9)=1,1,0) -> 0 | P9: =IF(AND(N9=1,S9=1,COUNTIFS($L$2:L9,L9,$J$2:J9,J9,$N$2:N9,1,$S$2:S9,1)=1),1,0) -> 0 | Q9: =IF(AND(N9=1,S9=1,COUNTIFS($L$2:L9,L9,$K$2:K9,K9,$N$2:N9,1,$S$2:S9,1)=1),1,0) -> 0 | R9: =IF(AND(N9=1,COUNTIFS($K$2:K9,K9,$L$2:L9,L9,$J$2:J9,J9,$N$2:N9,1)=1),1,0) -> 0 | S9: =IF(AND(K9<>"Context and provider model",K9<>"Motivation"),1,0) -> 0
A10: Cross-platform behavior | B10: Tools used alongside Rover, and what has moved off-Rover, under what conditions. | C10: ="This is where the off-platform-clients-leakage theme is most concentrated (23 of 29 tagged rows) and where per-participant leakage status is summarized. Across the 14 Pro providers: "&'Leakage - By Participant'!B19&" report no leakage, "&'Leakage - By Participant'!B20&" some leakage, "&'Leakage - By Participant'!B21&" partial leakage (~10% of clients, one participant), "&'Leakage - By Participant'!B22&" recurring leakage, "&'Leakage - By Participant'!B23&" explicitly declined a client request to move off-platform, "&'Leakage - By Participant'!B24&" unclear/unconfirmed (garbled transcript), and "&'Leakage - By Participant'!B25&" no stated instance. Full detail: 'Leakage - By Participant' sheet. IMPORTANT: leakage is a cross-cutting condition of the client relationship, not a single-stage event -- the same theme is also tagged in Client acquisition, Payments and earnings, and Growth and future plans (see those stages' notes in this column)." -> This is where the off-platform-clients-leakage theme is most concentrated (23 of 29 tagged rows) and where per-participant leakage status is summarized. Across the 14 Pro providers: 5 report no leakage, 3 some leakage, 1 partial leakage (~10% of clients, one participant), 1 recurring leakage, 2 explicitly declined a client request to move off-platform, 1 unclear/unconfirmed (garbled transcript), and 1 no stated instance. Full detail: 'Leakage - By Participant' sheet. IMPORTANT: leakage is a cross-cutting condition of the client relationship, not a single-stage event -- the same theme is also tagged in Client acquisition, Payments and earnings, and Growth and future plans (see those stages' notes in this column). | J10: ='Raw Atomic Data (Pro)'!A10 -> Andrew | K10: ='Raw Atomic Data (Pro)'!C10 -> Context and provider model | L10: ='Raw Atomic Data (Pro)'!D10 -> business-model-fit | M10: ='Raw Atomic Data (Pro)'!E10 -> fact | N10: =IF(OR(M10="friction",M10="need",M10="workaround"),1,0) -> 0 | O10: =IF(COUNTIFS($K$2:K10,K10,$L$2:L10,L10,$M$2:M10,M10,$J$2:J10,J10)=1,1,0) -> 1 | P10: =IF(AND(N10=1,S10=1,COUNTIFS($L$2:L10,L10,$J$2:J10,J10,$N$2:N10,1,$S$2:S10,1)=1),1,0) -> 0 | Q10: =IF(AND(N10=1,S10=1,COUNTIFS($L$2:L10,L10,$K$2:K10,K10,$N$2:N10,1,$S$2:S10,1)=1),1,0) -> 0 | R10: =IF(AND(N10=1,COUNTIFS($K$2:K10,K10,$L$2:L10,L10,$J$2:J10,J10,$N$2:N10,1)=1),1,0) -> 0 | S10: =IF(AND(K10<>"Context and provider model",K10<>"Motivation"),1,0) -> 0
A11: Growth and future plans | B11: Desired trajectory, scaling intentions, what would keep the provider on Rover long-term. | C11: Three off-platform-clients-leakage rows are tagged in this stage, but framed as commitment to Rover rather than attrition: Anita ("If not, I would have to go find another one"; "once I got signed on to Rover, I didn't look elsewhere") and Kristin ("Rover does the advertising for you... there's no reason to change that") both describe staying on Rover rather than switching platforms or going independent. Same theme, opposite direction from leakage -- included here because both concern the provider's relationship to Rover versus alternatives. | J11: ='Raw Atomic Data (Pro)'!A11 -> Andrew | K11: ='Raw Atomic Data (Pro)'!C11 -> Context and provider model | L11: ='Raw Atomic Data (Pro)'!D11 -> provider-background | M11: ='Raw Atomic Data (Pro)'!E11 -> fact | N11: =IF(OR(M11="friction",M11="need",M11="workaround"),1,0) -> 0 | O11: =IF(COUNTIFS($K$2:K11,K11,$L$2:L11,L11,$M$2:M11,M11,$J$2:J11,J11)=1,1,0) -> 1 | P11: =IF(AND(N11=1,S11=1,COUNTIFS($L$2:L11,L11,$J$2:J11,J11,$N$2:N11,1,$S$2:S11,1)=1),1,0) -> 0 | Q11: =IF(AND(N11=1,S11=1,COUNTIFS($L$2:L11,L11,$K$2:K11,K11,$N$2:N11,1,$S$2:S11,1)=1),1,0) -> 0 | R11: =IF(AND(N11=1,COUNTIFS($K$2:K11,K11,$L$2:L11,L11,$J$2:J11,J11,$N$2:N11,1)=1),1,0) -> 0 | S11: =IF(AND(K11<>"Context and provider model",K11<>"Motivation"),1,0) -> 0
J12: ='Raw Atomic Data (Pro)'!A12 -> Andrew | K12: ='Raw Atomic Data (Pro)'!C12 -> Context and provider model | L12: ='Raw Atomic Data (Pro)'!D12 -> capacity-multi-pet-management | M12: ='Raw Atomic Data (Pro)'!E12 -> fact | N12: =IF(OR(M12="friction",M12="need",M12="workaround"),1,0) -> 0 | O12: =IF(COUNTIFS($K$2:K12,K12,$L$2:L12,L12,$M$2:M12,M12,$J$2:J12,J12)=1,1,0) -> 1 | P12: =IF(AND(N12=1,S12=1,COUNTIFS($L$2:L12,L12,$J$2:J12,J12,$N$2:N12,1,$S$2:S12,1)=1),1,0) -> 0 | Q12: =IF(AND(N12=1,S12=1,COUNTIFS($L$2:L12,L12,$K$2:K12,K12,$N$2:N12,1,$S$2:S12,1)=1),1,0) -> 0 | R12: =IF(AND(N12=1,COUNTIFS($K$2:K12,K12,$L$2:L12,L12,$J$2:J12,J12,$N$2:N12,1)=1),1,0) -> 0 | S12: =IF(AND(K12<>"Context and provider model",K12<>"Motivation"),1,0) -> 0
A13: How to read this sheet: Section 1 is the sequential stage backbone (same 10 categories used to tag the raw transcripts). Section 2 lists every friction, need, and workaround tagged in each stage, with a live distinct-provider count pulled straight from Raw Atomic Data (Pro) -- workarounds were tagged in the source data but omitted from the first-draft map; they are included here. Section 3 rolls up themes that were tagged as a friction/need/workaround in MORE THAN ONE stage -- i.e. cross-cutting issues (like messaging mechanics or the meet-and-greet scheduling problem) that a stage-by-stage read alone would fragment and undercount. All counts in Sections 2-3 are live formulas built from a calculation-helper block in hidden columns J:S of this sheet, which mirror Raw Atomic Data (Pro) row-for-row -- unhide to audit. 'Context and provider model' and 'Motivation' categories are excluded throughout since they are background/outlook, not sequential workflow steps. | J13: ='Raw Atomic Data (Pro)'!A13 -> Andrew | K13: ='Raw Atomic Data (Pro)'!C13 -> Context and provider model | L13: ='Raw Atomic Data (Pro)'!D13 -> provider-background | M13: ='Raw Atomic Data (Pro)'!E13 -> fact | N13: =IF(OR(M13="friction",M13="need",M13="workaround"),1,0) -> 0 | O13: =IF(COUNTIFS($K$2:K13,K13,$L$2:L13,L13,$M$2:M13,M13,$J$2:J13,J13)=1,1,0) -> 0 | P13: =IF(AND(N13=1,S13=1,COUNTIFS($L$2:L13,L13,$J$2:J13,J13,$N$2:N13,1,$S$2:S13,1)=1),1,0) -> 0 | Q13: =IF(AND(N13=1,S13=1,COUNTIFS($L$2:L13,L13,$K$2:K13,K13,$N$2:N13,1,$S$2:S13,1)=1),1,0) -> 0 | R13: =IF(AND(N13=1,COUNTIFS($K$2:K13,K13,$L$2:L13,L13,$J$2:J13,J13,$N$2:N13,1)=1),1,0) -> 0 | S13: =IF(AND(K13<>"Context and provider model",K13<>"Motivation"),1,0) -> 0
J14: ='Raw Atomic Data (Pro)'!A14 -> Andrew | K14: ='Raw Atomic Data (Pro)'!C14 -> Context and provider model | L14: ='Raw Atomic Data (Pro)'!D14 -> business-model-fit | M14: ='Raw Atomic Data (Pro)'!E14 -> fact | N14: =IF(OR(M14="friction",M14="need",M14="workaround"),1,0) -> 0 | O14: =IF(COUNTIFS($K$2:K14,K14,$L$2:L14,L14,$M$2:M14,M14,$J$2:J14,J14)=1,1,0) -> 0 | P14: =IF(AND(N14=1,S14=1,COUNTIFS($L$2:L14,L14,$J$2:J14,J14,$N$2:N14,1,$S$2:S14,1)=1),1,0) -> 0 | Q14: =IF(AND(N14=1,S14=1,COUNTIFS($L$2:L14,L14,$K$2:K14,K14,$N$2:N14,1,$S$2:S14,1)=1),1,0) -> 0 | R14: =IF(AND(N14=1,COUNTIFS($K$2:K14,K14,$L$2:L14,L14,$J$2:J14,J14,$N$2:N14,1)=1),1,0) -> 0 | S14: =IF(AND(K14<>"Context and provider model",K14<>"Motivation"),1,0) -> 0
A15: Frictions, Needs & Workarounds by Stage (one row per Stage x Theme x Type tagged in Raw Atomic Data (Pro)) | J15: ='Raw Atomic Data (Pro)'!A15 -> Andrew | K15: ='Raw Atomic Data (Pro)'!C15 -> Context and provider model | L15: ='Raw Atomic Data (Pro)'!D15 -> provider-background | M15: ='Raw Atomic Data (Pro)'!E15 -> fact | N15: =IF(OR(M15="friction",M15="need",M15="workaround"),1,0) -> 0 | O15: =IF(COUNTIFS($K$2:K15,K15,$L$2:L15,L15,$M$2:M15,M15,$J$2:J15,J15)=1,1,0) -> 0 | P15: =IF(AND(N15=1,S15=1,COUNTIFS($L$2:L15,L15,$J$2:J15,J15,$N$2:N15,1,$S$2:S15,1)=1),1,0) -> 0 | Q15: =IF(AND(N15=1,S15=1,COUNTIFS($L$2:L15,L15,$K$2:K15,K15,$N$2:N15,1,$S$2:S15,1)=1),1,0) -> 0 | R15: =IF(AND(N15=1,COUNTIFS($K$2:K15,K15,$L$2:L15,L15,$J$2:J15,J15,$N$2:N15,1)=1),1,0) -> 0 | S15: =IF(AND(K15<>"Context and provider model",K15<>"Motivation"),1,0) -> 0
A16: Stage | B16: Theme | C16: Type | D16: Distinct providers (of 14 Pro) | E16: Cross-cutting across stages? | F16: Which providers (this stage) | G16: Representative observation | H16: Representative quote | J16: ='Raw Atomic Data (Pro)'!A16 -> Andrew | K16: ='Raw Atomic Data (Pro)'!C16 -> Context and provider model | L16: ='Raw Atomic Data (Pro)'!D16 -> capacity-multi-pet-management | M16: ='Raw Atomic Data (Pro)'!E16 -> fact | N16: =IF(OR(M16="friction",M16="need",M16="workaround"),1,0) -> 0 | O16: =IF(COUNTIFS($K$2:K16,K16,$L$2:L16,L16,$M$2:M16,M16,$J$2:J16,J16)=1,1,0) -> 0 | P16: =IF(AND(N16=1,S16=1,COUNTIFS($L$2:L16,L16,$J$2:J16,J16,$N$2:N16,1,$S$2:S16,1)=1),1,0) -> 0 | Q16: =IF(AND(N16=1,S16=1,COUNTIFS($L$2:L16,L16,$K$2:K16,K16,$N$2:N16,1,$S$2:S16,1)=1),1,0) -> 0 | R16: =IF(AND(N16=1,COUNTIFS($K$2:K16,K16,$L$2:L16,L16,$J$2:J16,J16,$N$2:N16,1)=1),1,0) -> 0 | S16: =IF(AND(K16<>"Context and provider model",K16<>"Motivation"),1,0) -> 0
A17: Client acquisition | B17: client-acquisition-discovery | C17: friction | D17: =SUMIFS($O$2:$O$978,$K$2:$K$978,$A17,$L$2:$L$978,$B17,$M$2:$M$978,$C17) -> 2 | E17: =IF(SUMIFS($Q$2:$Q$978,$L$2:$L$978,$B17)>1,"Yes -- also friction/need/workaround in "&(SUMIFS($Q$2:$Q$978,$L$2:$L$978,$B17)-1)&" other stage(s); see Section 3","No -- stage-specific in this dataset") -> Yes -- also friction/need/workaround in 2 other stage(s); see Section 3 | F17: Ashley P., Naomi | G17: [Naomi] A share of Rover message requests don't convert, including people who 'ghost' after messaging, which she says leads her to contact multiple prospects to fill her available slots and can result in overbooking ("there's a lot of people who just have like they'll send a request and it'll never come through so that's why you sometimes end up over booked because you have to talk to multiple people if you want to get to your number"). | H17: there's a lot of people who just have like they'll send a request and it'll never come through so that's why you sometimes end up over booked because you have to talk to multiple people if you want to get to your number | J17: ='Raw Atomic Data (Pro)'!A17 -> Andrew | K17: ='Raw Atomic Data (Pro)'!C17 -> Context and provider model | L17: ='Raw Atomic Data (Pro)'!D17 -> provider-background | M17: ='Raw Atomic Data (Pro)'!E17 -> fact | N17: =IF(OR(M17="friction",M17="need",M17="workaround"),1,0) -> 0 | O17: =IF(COUNTIFS($K$2:K17,K17,$L$2:L17,L17,$M$2:M17,M17,$J$2:J17,J17)=1,1,0) -> 0 | P17: =IF(AND(N17=1,S17=1,COUNTIFS($L$2:L17,L17,$J$2:J17,J17,$N$2:N17,1,$S$2:S17,1)=1),1,0) -> 0 | Q17: =IF(AND(N17=1,S17=1,COUNTIFS($L$2:L17,L17,$K$2:K17,K17,$N$2:N17,1,$S$2:S17,1)=1),1,0) -> 0 | R17: =IF(AND(N17=1,COUNTIFS($K$2:K17,K17,$L$2:L17,L17,$J$2:J17,J17,$N$2:N17,1)=1),1,0) -> 0 | S17: =IF(AND(K17<>"Context and provider model",K17<>"Motivation"),1,0) -> 0
