Workbook

Sheet ⚙️ Settings
A1: Study Start Date (fill in once confirmed): | B1: 46213
A3: Week # in the Entries and Weekly Digest tabs is calculated from this date. Leave it blank and those columns will show blank; fill it in once your kickoff date is confirmed and everything recalculates automatically.

Sheet 📋 Entries
A1: ROVER DIARY STUDY — SYNTHESIS ANALYSIS TOOL
A2: Date | B2: User Name | C2: Segment | D2: Question | E2: Task Type | F2: Experience Moment | G2: Workflow Area | H2: Tool Used | I2: Platform Role | J2: Behavior | K2: Need | L2: Friction | M2: Value | N2: Signal | O2: Emotion | P2: Opportunity | Q2: Description | R2: Has Attachment? | S2: Attachment | T2: Link | U2: Observations | V2: Week #
A3: 46217 | B3: Richard | C3: M | D3: Topic 2. That's me | Q3: I’m Richard and I live in Austin, Texas. I’m 65 years old and I am a retired medical doctor. I have been dog sitting for my neighbors since the pandemic started. Then one of my neighbors mentioned Rover and I started doing even more pet sitting in the Northwest Austin area. I enjoy reading and researching, weightlifting and walking, and fresh air and sunshine. | R3: No | V3: =IF($A3="","",IF('⚙️ Settings'!$B$1="","",INT(($A3-'⚙️ Settings'!$B$1)/7)+1))
A4: 46217 | B4: Shania | C4: T | D4: Topic 1. Welcome | Q4: Sounds good! | R4: No | V4: =IF($A4="","",IF('⚙️ Settings'!$B$1="","",INT(($A4-'⚙️ Settings'!$B$1)/7)+1))
A5: 46217 | B5: Shania | C5: T | D5: Topic 2. That's me | Q5: I’m Shania. | R5: No | V5: =IF($A5="","",IF('⚙️ Settings'!$B$1="","",INT(($A5-'⚙️ Settings'!$B$1)/7)+1))
A6: 46212 | B6: Kristin | C6: T | D6: Topic 1. Welcome | Q6: Got it! | R6: No | V6: =IF($A6="","",IF('⚙️ Settings'!$B$1="","",INT(($A6-'⚙️ Settings'!$B$1)/7)+1))
A7: 46212 | B7: Kristin | C7: T | D7: Topic 2. That's me | Q7: My name is Kristen. I live in New Mexico, USA. 41. I own my own home. Program Manager. I enjoy reading, traveling and going to concerts. | R7: No | V7: =IF($A7="","",IF('⚙️ Settings'!$B$1="","",INT(($A7-'⚙️ Settings'!$B$1)/7)+1))
A8: 46212 | B8: Tifany | C8: T | D8: Topic 2. That's me | Q8: Hello! I’m Tifany! I’m from Washington state in the good ole US-of-A. I’m 42 years old, I’m single and live alone, and I’m a Bible Instructor as my main source of income. I also do Rover, and have an independent, small business caring for pets called Havenly Paws. Things I enjoy doing would include scrolling Facebook reels about stupid mukbangs (why? I have absolutely no idea because I don’t even eat that stuff lol!), spending time with my 5 month old grandbaby, church functions, ministry, learning more about God’s love for us, socializing, new adventures, sewing and quilting, helping others, learning and playing piano, singing, and most forms of creativity. I also enjoy debating, which I know that most people hate, but it’s because I really love deep thinking and the opportunity to see perspectives I haven’t yet considered. I’m more than willing to be wrong and it’s not that I need to “win”, I just want to learn more — I love learning! But being right can be really fun too (haha). Philosophizing is totes exciting! | R8: Yes | S8: Photo | V8: =IF($A8="","",IF('⚙️ Settings'!$B$1="","",INT(($A8-'⚙️ Settings'!$B$1)/7)+1))
A9: 46212 | B9: Tifany | C9: T | D9: Topic 1. Welcome | Q9: Thank you! | R9: No | V9: =IF($A9="","",IF('⚙️ Settings'!$B$1="","",INT(($A9-'⚙️ Settings'!$B$1)/7)+1))
A10: 46212 | B10: Kristin | C10: T | D10: Topic 3. Me on Rover | Q10: I have been using Rover since 2018. I started using Rover for supplemental income when I was promoted at my full-time job and was no longer receiving overtime. I provide dog- walking, dropin visits and housesitting. Total bookings 1705 Petsitting experience includes pups and kitties to seniors. Medication administering, I love my regulars and meeting new clients. | R10: No | V10: =IF($A10="","",IF('⚙️ Settings'!$B$1="","",INT(($A10-'⚙️ Settings'!$B$1)/7)+1))
A11: 46212 | B11: Kristin | C11: T | D11: Topic 3. Me on Rover | R11: Yes | S11: Photo | V11: =IF($A11="","",IF('⚙️ Settings'!$B$1="","",INT(($A11-'⚙️ Settings'!$B$1)/7)+1))
A12: 46212 | B12: Deborah | C12: N | D12: Topic 2. That's me | Q12: Deborah, but I prefer Debbie. I live in the US in Ohio. I am 74. I am retired and live alone. I enjoy nature, art, and music. I hike often and frequent indoor and outdoor concerts. I am an artist, working in acrylics with abstract and hand-painted details. | R12: No | V12: =IF($A12="","",IF('⚙️ Settings'!$B$1="","",INT(($A12-'⚙️ Settings'!$B$1)/7)+1))
A13: 46212 | B13: Deborah | C13: N | D13: Topic 3. Me on Rover | Q13: I recently started using Rover. I started because I sit with my families dogs and love doing it. I do not have a dog of my own any longer. I offer in home sitting for long weekends or extended vacations. I got my first booking within two days of posting my Rover availablity. I’ve found getting started on Rover easy. The tips on use of the site that were emailed to me later have been timely and helpful | R13: No | V13: =IF($A13="","",IF('⚙️ Settings'!$B$1="","",INT(($A13-'⚙️ Settings'!$B$1)/7)+1))
A14: 46212 | B14: Deborah | C14: N | D14: Topic 4. My motivation to become a pet sitter | Q14: I had a companion, some called her a dog, but she was my best friend. I could never replace her, but found I could get and give love from my families (my grand puppies) dogs. My daughter suggested I check out Rover as a way to combine my love of dogs, make best use of my available time, and earn some extra money. I stay in the clients home, follow their instructions and dogs habits to the letter. i.e. no people food. I would like to pick up long weekends or extended stay vacations once a month or so for extra income. | R14: No | V14: =IF($A14="","",IF('⚙️ Settings'!$B$1="","",INT(($A14-'⚙️ Settings'!$B$1)/7)+1))
A15: 46212 | B15: Deborah | C15: N | D15: Topic 2. That's me | R15: Yes | S15: Photo | V15: =IF($A15="","",IF('⚙️ Settings'!$B$1="","",INT(($A15-'⚙️ Settings'!$B$1)/7)+1))
A16: 46212 | B16: Deborah | C16: N | D16: Topic 1. Welcome | Q16: I found Rover easy to use. I have two meet and greets set for next week | R16: No | V16: =IF($A16="","",IF('⚙️ Settings'!$B$1="","",INT(($A16-'⚙️ Settings'!$B$1)/7)+1))
A17: 46212 | B17: Deborah | C17: N | D17: Topic 1. Welcome | Q17: I love dogs and animals in general. This is me bottle feeding a 9 month old baby bear. The coat is course and rough. This is Bean. He insisted on being pet as he drank. If I stopped petting he whined. | R17: Yes | S17: Photo | V17: =IF($A17="","",IF('⚙️ Settings'!$B$1="","",INT(($A17-'⚙️ Settings'!$B$1)/7)+1))
A18: 46213 | B18: Joey | C18: M | D18: Topic 1. Welcome | Q18: Thank you Myriel and Lisa for the introduction. Looking forward to meeting you soon! | R18: No | V18: =IF($A18="","",IF('⚙️ Settings'!$B$1="","",INT(($A18-'⚙️ Settings'!$B$1)/7)+1))
A19: 46213 | B19: Becky | C19: T | D19: Topic 1. Welcome | Q19: Acknowledged | R19: No | V19: =IF($A19="","",IF('⚙️ Settings'!$B$1="","",INT(($A19-'⚙️ Settings'!$B$1)/7)+1))
A20: 46217 | B20: Shania | C20: T | D20: Topic 1. Welcome | Q20: Sounds good! | R20: No | S20: None | V20: =IF($A20="","",IF('⚙️ Settings'!$B$1="","",INT(($A20-'⚙️ Settings'!$B$1)/7)+1))
A21: 46219 | B21: Alexandra | C21: N | D21: Topic 1. Welcome | Q21: Thank you! Happy to belong to this project investigation! | R21: No | S21: None | V21: =IF($A21="","",IF('⚙️ Settings'!$B$1="","",INT(($A21-'⚙️ Settings'!$B$1)/7)+1))
A22: 46214 | B22: Annabelle | C22: N | D22: Topic 2. That's me | Q22: My name is Bella and I live in Denver, CO in the United States. I am 23 years old and am living with a roommate in an apartment. I am in grad school getting my masters in social work and also working as a therapist for adolescents. I enjoy skiing, hiking, listening to music, being outside, and meeting new people! | R22: No | S22: None | V22: =IF($A22="","",IF('⚙️ Settings'!$B$1="","",INT(($A22-'⚙️ Settings'!$B$1)/7)+1))
A23: 46216 | B23: Naomi | C23: M | D23: Topic 2. That's me | Q23: Naomi USA 37 I own a large single family home in the bronx with a big back yard. I rent out airbnb and 2 long term bedrooms. I used to work in Tech, now I earn rental income and work as a personal trainer, group class instructor and dog sitter. I enjoy outside activities, yoga and MMA. | R23: No | S23: None | V23: =IF($A23="","",IF('⚙️ Settings'!$B$1="","",INT(($A23-'⚙️ Settings'!$B$1)/7)+1))
A24: 46216 | B24: Amy | C24: T | D24: Topic 2. That's me | Q24: My name is Amy. I live near Pittsburgh, Pennsylvania in the USA. I am 60 years old and live in a suburban home with my husband, 2 dogs and cat. We have 3 adult children, 2 of which live nearby. I enjoy walking, swimming, reading, true crime, crocheting, baking and spending time with my kids. I retired from teaching elementary music in June of 24 after 32 years in the profession. I miss the kids, but love the freedom of retirement. | R24: No | S24: None | V24: =IF($A24="","",IF('⚙️ Settings'!$B$1="","",INT(($A24-'⚙️ Settings'!$B$1)/7)+1))
A25: 46217 | B25: Colin | C25: T | D25: Topic 2. That's me | Q25: My name is Colin, I'm originally from Colorado in the USA but now live in Toronto, Canada with my wife and our dog, Pepsi. I have been a teacher for 15 years but I am sick of it and ready for a change. I was fortunate enough to be able to teach abroad in Asia for several years and spend a lot of time solo traveling to new places. I used to love rock and roll, going to the movies, and camping in the mountains. I still like all those but now that I'm older, I just want to spend quiet times with my wife and dog! | R25: No | S25: None | V25: =IF($A25="","",IF('⚙️ Settings'!$B$1="","",INT(($A25-'⚙️ Settings'!$B$1)/7)+1))
A26: 46217 | B26: Caroline | C26: M | D26: Topic 2. That's me | Q26: My name is Caroline and I am from the US born in Ohio and now living in the rural mountains of North Carolina. I am 43 and bought a home where I have a crystal store I sell online as well as taking over the family business of a travel agency! Before this I did Human Resources for 14 years and was a consultant too so hopefully that will help me find great discoveries to help you all in this research! I love to read, see live music and be in nature kayaking! | R26: No | S26: None | V26: =IF($A26="","",IF('⚙️ Settings'!$B$1="","",INT(($A26-'⚙️ Settings'!$B$1)/7)+1))
A27: 46218 | B27: Rachel | C27: N | D27: Topic 2. That's me | Q27: Hi! My name is Rachel, and I like in California. I'm 27 years old and live alone! I'm a city planner working for a government agency. I love hanging out with friends, going to the park, reading, dancing, playing tennis, and thrifting! I also LOVE dogs! | R27: No | S27: None | V27: =IF($A27="","",IF('⚙️ Settings'!$B$1="","",INT(($A27-'⚙️ Settings'!$B$1)/7)+1))
A28: 46218 | B28: Bruna | C28: T | D28: Topic 2. That's me | Q28: Hi! My name is Bruna, I'm 28 years old and I live in New Westminster, British Columbia, Canada, with my boyfriend. I'm from Brazil and have been living in Canada for about six years. I'm a professional dog trainer and pet care provider, and I run my own dog training business. I have a background in neuroscience and biomedicine, and I currently offer dog boarding through Rover. Dogs are a very big part of my daily life, both professionally and personally. Outside of work, I enjoy studying dog behaviour and continuing my education, singing, playing guitar, skiing, spending time with friends and travelling. I also really enjoy learning in general and I'm usually taking a course or becoming interested in a new subject. | R28: No | S28: None | V28: =IF($A28="","",IF('⚙️ Settings'!$B$1="","",INT(($A28-'⚙️ Settings'!$B$1)/7)+1))
A29: 46218 | B29: Ashley | C29: N | D29: Topic 2. That's me | Q29: My name is Ashley. I live in the United States. Jacksonville, Florida in the Springfield Area. I'm 24. I live in a two bedroom apartment with my fiancé and our son. I enjoy working at my job as a server assistant, spending quality time with family and friends, being a tarot reader and creating my botanical products, and spending time outside and with my friends who has pets themselves. | R29: No | S29: None | V29: =IF($A29="","",IF('⚙️ Settings'!$B$1="","",INT(($A29-'⚙️ Settings'!$B$1)/7)+1))
A30: 46218 | B30: Emma | C30: M | D30: Topic 2. That's me | Q30: -Emma -USA, Ohio -27 -Rent an apartment, living alone with my 2 cats! -I work as a course scheduler for the business school at a university -I enjoy running, reading, listening to music (mostly kpop), watching soccer/football, and yoga -I'm left-handed -I've traveled to France, Spain, and Canada. My travel bucket list includes Japan, Iceland, Australia, Italy, Korea, Germany, Ireland, Norway, Turkey, Thailand, Morocco, and Switzerland -I studied international relations and Spanish in university | R30: No | S30: None | V30: =IF($A30="","",IF('⚙️ Settings'!$B$1="","",INT(($A30-'⚙️ Settings'!$B$1)/7)+1))
A31: 46219 | B31: Alexandra | C31: N | D31: Topic 2. That's me | Q31: Hey! My name is Alexandra, currently living in Alberta,Canada! I have 25 years old and I live with my sister. My current profession is Administrative Assistant and pet sitter. I enjoy share my time with pets, dancing, listen to music and eat desserts 😊❤️ | R31: No | S31: None | V31: =IF($A31="","",IF('⚙️ Settings'!$B$1="","",INT(($A31-'⚙️ Settings'!$B$1)/7)+1))
... A36: 46217 | B36: Colin | C36: T | D36: Topic 3. Me on Rover | Q36: I started using Rover in February 2025. Our dog at the time, Poncho, was diagnosed with meningitis in the fall of 2024 and sadly passed away a few months later after fighting so hard. We were very obviously devastated to lose Poncho, so we used Rover as a form of therapy for ourselves, a supplemental income, and as a way to spend more time with cute dogs. Our Rover business started slowly with mostly local walks and the occasional boarding. But soon after school ended and families were traveling during summer so we got a lot of boarding and house sitting requests. Altogether we've had ~20 different dogs board with us in our home, most for 3-10 day stays. we have had a few dogs stay with us for up to three weeks at a time though. I have also done house sitting about 10 times total but all for repeat clients. because we have our own dog now and live in a smaller apartment, we are only taking boarding requests from previous clients. currently we walk several dogs in the neighborhood and board a dog once every couple months. We also have one family who travel a lot and ask me to house/dog sit while they are away, usually for ~7 days at a time | R36: No | S36: None | V36: =IF($A36="","",IF('⚙️ Settings'!$B$1="","",INT(($A36-'⚙️ Settings'!$B$1)/7)+1))
A37: 46212 | B37: Deborah | C37: N | D37: Topic 1. Welcome | Q37: I found Rover easy to use. I have two meet and greets set for next week | R37: No | V37: =IF($A37="","",IF('⚙️ Settings'!$B$1="","",INT(($A37-'⚙️ Settings'!$B$1)/7)+1))
A38: 46220 | B38: Anita | C38: T | D38: Topic 1. Welcome | Q38: I am Anita | R38: No | V38: =IF($A38="","",IF('⚙️ Settings'!$B$1="","",INT(($A38-'⚙️ Settings'!$B$1)/7)+1))
A39: 46222 | B39: Emma | C39: M | D39: Topic 1. Welcome | Q39: Thank you!! | R39: No | V39: =IF($A39="","",IF('⚙️ Settings'!$B$1="","",INT(($A39-'⚙️ Settings'!$B$1)/7)+1))
A40: 46224 | B40: Alexia | C40: M | D40: Topic 1. Welcome | Q40: Sounds great thank you! | R40: No | V40: =IF($A40="","",IF('⚙️ Settings'!$B$1="","",INT(($A40-'⚙️ Settings'!$B$1)/7)+1))
A41: 46225 | B41: Dawn | C41: T | D41: Topic 1. Welcome | Q41: Took care of sweet golden doodle named Emi at my house. This was a booking through Rover. | R41: Yes | S41: Photo | V41: =IF($A41="","",IF('⚙️ Settings'!$B$1="","",INT(($A41-'⚙️ Settings'!$B$1)/7)+1))
A42: 46226 | B42: Emily | C42: N | D42: Topic 1. Welcome | Q42: Excited to join the study! | R42: No | V42: =IF($A42="","",IF('⚙️ Settings'!$B$1="","",INT(($A42-'⚙️ Settings'!$B$1)/7)+1))
A43: 46212 | B43: Kristin | C43: T | D43: Topic 2. That's me | Q43: My name is Kristen. I live in New Mexico, USA. 41. I own my own home. Program Manager. I enjoy reading, traveling and going to concerts. | R43: No | V43: =IF($A43="","",IF('⚙️ Settings'!$B$1="","",INT(($A43-'⚙️ Settings'!$B$1)/7)+1))
A44: 46212 | B44: Tifany | C44: T | D44: Topic 2. That's me | Q44: Hello! I’m Tifany! I’m from Washington state in the good ole US-of-A. I’m 42 years old, I’m single and live alone, and I’m a Bible Instructor as my main source of income. I also do Rover, and have an independent, small business caring for pets called Havenly Paws. Things I enjoy doing would include scrolling Facebook reels about stupid mukbangs (why? I have absolutely no idea because I don’t even eat that stuff lol!), spending time with my 5 month old grandbaby, church functions, ministry, learning more about God’s love for us, socializing, new adventures, sewing and quilting, helping others, learning and playing piano, singing, and most forms of creativity. I also enjoy debating, which I know that most people hate, but it’s because I really love deep thinking and the opportunity to see perspectives I haven’t yet considered. I’m more than willing to be wrong and it’s not that I need to “win”, I just want to learn more — I love learning! But being right can be really fun too (haha). Philosophizing is totes exciting! | R44: Yes | S44: Photo | V44: =IF($A44="","",IF('⚙️ Settings'!$B$1="","",INT(($A44-'⚙️ Settings'!$B$1)/7)+1))
...

Sheet 🏷️ Tag Taxonomy
A1: TAG TAXONOMY — ROVER DIARY STUDY
A2: Tag Name | B2: Category | C2: Layer | D2: Description
A3: DESCRIPTIVE TAGS
A4: Workflow Area
A5: Relationship management | B5: Workflow Area | C5: Descriptive | D5: Ongoing client retention and nurturing
A6: Scheduling | B6: Workflow Area | C6: Descriptive | D6: Booking and calendar coordination
A7: Communication | B7: Workflow Area | C7: Descriptive | D7: Client-provider messaging
A8: Payments | B8: Workflow Area | C8: Descriptive | D8: Invoicing, rates, payout
A9: Business administration | B9: Workflow Area | C9: Descriptive | D9: Profile, records, reporting
A10: Trust & safety | B10: Workflow Area | C10: Descriptive | D10: Background checks, insurance, incident handling
A11: Client acquisition | B11: Workflow Area | C11: Descriptive | D11: Finding new clients, marketplace browsing
A12: Tool Used
A13: Rover | B13: Tool Used | C13: Descriptive | D13: Native platform action
A14: Google Calendar | B14: Tool Used | C14: Descriptive | D14: External scheduling
A15: Apple Calendar | B15: Tool Used | C15: Descriptive | D15: External scheduling
A16: Spreadsheet | B16: Tool Used | C16: Descriptive | D16: Custom tracking
A17: Text messages | B17: Tool Used | C17: Descriptive | D17: Off-platform comms
A18: WhatsApp | B18: Tool Used | C18: Descriptive | D18: Off-platform comms
A19: Notes app | B19: Tool Used | C19: Descriptive | D19: Personal records
A20: Facebook group | B20: Tool Used | C20: Descriptive | D20: Community/referral
A21: Email | B21: Tool Used | C21: Descriptive | D21: Off-platform comms
A22: Phone call | B22: Tool Used | C22: Descriptive | D22: Off-platform comms
A23: Behavior
A24: Moved communication off-platform | B24: Behavior | C24: Descriptive | D24: Shifted messages to text/WhatsApp/etc.
A25: Used Google Calendar | B25: Behavior | C25: Descriptive | D25: Managed bookings externally
A26: Accepted booking | B26: Behavior | C26: Descriptive | D26: Confirmed a service request
A27: Declined booking | B27: Behavior | C27: Descriptive | D27: Turned down a service request
A28: Created workaround | B28: Behavior | C28: Descriptive | D28: Built a custom solution outside Rover
A29: Contacted client directly | B29: Behavior | C29: Descriptive | D29: Bypassed Rover messaging
A30: Managed schedule externally | B30: Behavior | C30: Descriptive | D30: Primary scheduling not on Rover
A31: Tracked info externally | B31: Behavior | C31: Descriptive | D31: Client notes kept outside platform
A32: Emotion
A33: Confident | B33: Emotion | C33: Descriptive | D33: Provider feels in control and capable
A34: Frustrated | B34: Emotion | C34: Descriptive | D34: Friction causing negative affect
A35: Proud | B35: Emotion | C35: Descriptive | D35: Positive achievement
A36: Overwhelmed | B36: Emotion | C36: Descriptive | D36: Volume or complexity is too much
A37: Uncertain | B37: Emotion | C37: Descriptive | D37: Unclear what to do or expect
A38: Relieved | B38: Emotion | C38: Descriptive | D38: Stress resolved
A39: Excited | B39: Emotion | C39: Descriptive | D39: Positive anticipation
A40: Satisfied | B40: Emotion | C40: Descriptive | D40: Needs met in the moment
...

Sheet 📊 Summary
A1: SUMMARY DASHBOARD — Use pivot tables to analyse the Entries sheet
A2: HOW TO BUILD PIVOT ANALYSES
A3: 1. Click any cell in the 📋 Entries sheet
A4: 2. Insert → PivotTable → New Worksheet (or Existing Sheet)
A5: 3. Drag fields to Rows, Columns, Values, or Filters
A6: KEY QUESTIONS TO ANSWER
A7: Platform Role by Segment → Rows: Segment | Cols: Platform Role | Values: Count
A8: Workflow Area by Friction → Where are providers struggling most?
A9: Tool Used by Segment → Which tools are providers using outside Rover?
A10: Signal by Week → How does diversion risk evolve over 9 weeks? (See 📅 Weekly Digest tab for a ready-made breakdown)
A11: Emotion by Workflow Area → Where does Rover create/reduce stress?
A12: Opportunity by Platform Role → Where is Rover most irrelevant?
A13: QUICK COUNTS (update these formulas)
A15: Metric | B15: Count
A16: Total entries | B16: =COUNTA('📋 Entries'!A3:A302)
A17: Unique providers | B17: =IFERROR(SUMPRODUCT(1/COUNTIF('📋 Entries'!B3:B302,'📋 Entries'!B3:B302)),0)
A18: Entries flagged as Diversion Risk | B18: =COUNTIF('📋 Entries'!N3:N302,"Diversion risk")
A19: Entries where Platform Role = Barrier | B19: =COUNTIF('📋 Entries'!I3:I302,"Barrier")
A20: Entries where Platform Role = Essential | B20: =COUNTIF('📋 Entries'!I3:I302,"Essential")
A21: Entries with Friction tagged | B21: =COUNTA('📋 Entries'!L3:L302)
A22: Entries with Opportunity tagged | B22: =COUNTA('📋 Entries'!P3:P302)

Sheet 📅 Weekly Digest
A1: WEEKLY DIGEST — auto-updates as entries are logged (requires Study Start Date set in ⚙️ Settings)
A3: Week # | B3: Total Entries | C3: Unique Providers | D3: Platform Role = Essential | E3: Platform Role = Barrier | F3: Signal = Diversion Risk | G3: Signal = Growing Loyalty | H3: Friction Tagged | I3: Opportunity Tagged
A4: 1 | B4: =COUNTIF('📋 Entries'!$V$3:$V$302,$A4) | C4: =IFERROR(SUMPRODUCT((('📋 Entries'!$V$3:$V$302=$A4))/COUNTIFS('📋 Entries'!$B$3:$B$302,'📋 Entries'!$B$3:$B$302&"",'📋 Entries'!$V$3:$V$302,'📋 Entries'!$V$3:$V$302&"")),0) | D4: =COUNTIFS('📋 Entries'!$V$3:$V$302,$A4,'📋 Entries'!$I$3:$I$302,"Essential") | E4: =COUNTIFS('📋 Entries'!$V$3:$V$302,$A4,'📋 Entries'!$I$3:$I$302,"Barrier") | F4: =COUNTIFS('📋 Entries'!$V$3:$V$302,$A4,'📋 Entries'!$N$3:$N$302,"Diversion risk") | G4: =COUNTIFS('📋 Entries'!$V$3:$V$302,$A4,'📋 Entries'!$N$3:$N$302,"Growing loyalty") | H4: =COUNTIFS('📋 Entries'!$V$3:$V$302,$A4,'📋 Entries'!$L$3:$L$302,"<>") | I4: =COUNTIFS('📋 Entries'!$V$3:$V$302,$A4,'📋 Entries'!$P$3:$P$302,"<>")
A5: 2 | B5: =COUNTIF('📋 Entries'!$V$3:$V$302,$A5) | C5: =IFERROR(SUMPRODUCT((('📋 Entries'!$V$3:$V$302=$A5))/COUNTIFS('📋 Entries'!$B$3:$B$302,'📋 Entries'!$B$3:$B$302&"",'📋 Entries'!$V$3:$V$302,'📋 Entries'!$V$3:$V$302&"")),0) | D5: =COUNTIFS('📋 Entries'!$V$3:$V$302,$A5,'📋 Entries'!$I$3:$I$302,"Essential") | E5: =COUNTIFS('📋 Entries'!$V$3:$V$302,$A5,'📋 Entries'!$I$3:$I$302,"Barrier") | F5: =COUNTIFS('📋 Entries'!$V$3:$V$302,$A5,'📋 Entries'!$N$3:$N$302,"Diversion risk") | G5: =COUNTIFS('📋 Entries'!$V$3:$V$302,$A5,'📋 Entries'!$N$3:$N$302,"Growing loyalty") | H5: =COUNTIFS('📋 Entries'!$V$3:$V$302,$A5,'📋 Entries'!$L$3:$L$302,"<>") | I5: =COUNTIFS('📋 Entries'!$V$3:$V$302,$A5,'📋 Entries'!$P$3:$P$302,"<>")
A6: 3 | B6: =COUNTIF('📋 Entries'!$V$3:$V$302,$A6) | C6: =IFERROR(SUMPRODUCT((('📋 Entries'!$V$3:$V$302=$A6))/COUNTIFS('📋 Entries'!$B$3:$B$302,'📋 Entries'!$B$3:$B$302&"",'📋 Entries'!$V$3:$V$302,'📋 Entries'!$V$3:$V$302&"")),0) | D6: =COUNTIFS('📋 Entries'!$V$3:$V$302,$A6,'📋 Entries'!$I$3:$I$302,"Essential") | E6: =COUNTIFS('📋 Entries'!$V$3:$V$302,$A6,'📋 Entries'!$I$3:$I$302,"Barrier") | F6: =COUNTIFS('📋 Entries'!$V$3:$V$302,$A6,'📋 Entries'!$N$3:$N$302,"Diversion risk") | G6: =COUNTIFS('📋 Entries'!$V$3:$V$302,$A6,'📋 Entries'!$N$3:$N$302,"Growing loyalty") | H6: =COUNTIFS('📋 Entries'!$V$3:$V$302,$A6,'📋 Entries'!$L$3:$L$302,"<>") | I6: =COUNTIFS('📋 Entries'!$V$3:$V$302,$A6,'📋 Entries'!$P$3:$P$302,"<>")
A7: 4 | B7: =COUNTIF('📋 Entries'!$V$3:$V$302,$A7) | C7: =IFERROR(SUMPRODUCT((('📋 Entries'!$V$3:$V$302=$A7))/COUNTIFS('📋 Entries'!$B$3:$B$302,'📋 Entries'!$B$3:$B$302&"",'📋 Entries'!$V$3:$V$302,'📋 Entries'!$V$3:$V$302&"")),0) | D7: =COUNTIFS('📋 Entries'!$V$3:$V$302,$A7,'📋 Entries'!$I$3:$I$302,"Essential") | E7: =COUNTIFS('📋 Entries'!$V$3:$V$302,$A7,'📋 Entries'!$I$3:$I$302,"Barrier") | F7: =COUNTIFS('📋 Entries'!$V$3:$V$302,$A7,'📋 Entries'!$N$3:$N$302,"Diversion risk") | G7: =COUNTIFS('📋 Entries'!$V$3:$V$302,$A7,'📋 Entries'!$N$3:$N$302,"Growing loyalty") | H7: =COUNTIFS('📋 Entries'!$V$3:$V$302,$A7,'📋 Entries'!$L$3:$L$302,"<>") | I7: =COUNTIFS('📋 Entries'!$V$3:$V$302,$A7,'📋 Entries'!$P$3:$P$302,"<>")
A8: 5 | B8: =COUNTIF('📋 Entries'!$V$3:$V$302,$A8) | C8: =IFERROR(SUMPRODUCT((('📋 Entries'!$V$3:$V$302=$A8))/COUNTIFS('📋 Entries'!$B$3:$B$302,'📋 Entries'!$B$3:$B$302&"",'📋 Entries'!$V$3:$V$302,'📋 Entries'!$V$3:$V$302&"")),0) | D8: =COUNTIFS('📋 Entries'!$V$3:$V$302,$A8,'📋 Entries'!$I$3:$I$302,"Essential") | E8: =COUNTIFS('📋 Entries'!$V$3:$V$302,$A8,'📋 Entries'!$I$3:$I$302,"Barrier") | F8: =COUNTIFS('📋 Entries'!$V$3:$V$302,$A8,'📋 Entries'!$N$3:$N$302,"Diversion risk") | G8: =COUNTIFS('📋 Entries'!$V$3:$V$302,$A8,'📋 Entries'!$N$3:$N$302,"Growing loyalty") | H8: =COUNTIFS('📋 Entries'!$V$3:$V$302,$A8,'📋 Entries'!$L$3:$L$302,"<>") | I8: =COUNTIFS('📋 Entries'!$V$3:$V$302,$A8,'📋 Entries'!$P$3:$P$302,"<>")
A9: 6 | B9: =COUNTIF('📋 Entries'!$V$3:$V$302,$A9) | C9: =IFERROR(SUMPRODUCT((('📋 Entries'!$V$3:$V$302=$A9))/COUNTIFS('📋 Entries'!$B$3:$B$302,'📋 Entries'!$B$3:$B$302&"",'📋 Entries'!$V$3:$V$302,'📋 Entries'!$V$3:$V$302&"")),0) | D9: =COUNTIFS('📋 Entries'!$V$3:$V$302,$A9,'📋 Entries'!$I$3:$I$302,"Essential") | E9: =COUNTIFS('📋 Entries'!$V$3:$V$302,$A9,'📋 Entries'!$I$3:$I$302,"Barrier") | F9: =COUNTIFS('📋 Entries'!$V$3:$V$302,$A9,'📋 Entries'!$N$3:$N$302,"Diversion risk") | G9: =COUNTIFS('📋 Entries'!$V$3:$V$302,$A9,'📋 Entries'!$N$3:$N$302,"Growing loyalty") | H9: =COUNTIFS('📋 Entries'!$V$3:$V$302,$A9,'📋 Entries'!$L$3:$L$302,"<>") | I9: =COUNTIFS('📋 Entries'!$V$3:$V$302,$A9,'📋 Entries'!$P$3:$P$302,"<>")
A10: 7 | B10: =COUNTIF('📋 Entries'!$V$3:$V$302,$A10) | C10: =IFERROR(SUMPRODUCT((('📋 Entries'!$V$3:$V$302=$A10))/COUNTIFS('📋 Entries'!$B$3:$B$302,'📋 Entries'!$B$3:$B$302&"",'📋 Entries'!$V$3:$V$302,'📋 Entries'!$V$3:$V$302&"")),0) | D10: =COUNTIFS('📋 Entries'!$V$3:$V$302,$A10,'📋 Entries'!$I$3:$I$302,"Essential") | E10: =COUNTIFS('📋 Entries'!$V$3:$V$302,$A10,'📋 Entries'!$I$3:$I$302,"Barrier") | F10: =COUNTIFS('📋 Entries'!$V$3:$V$302,$A10,'📋 Entries'!$N$3:$N$302,"Diversion risk") | G10: =COUNTIFS('📋 Entries'!$V$3:$V$302,$A10,'📋 Entries'!$N$3:$N$302,"Growing loyalty") | H10: =COUNTIFS('📋 Entries'!$V$3:$V$302,$A10,'📋 Entries'!$L$3:$L$302,"<>") | I10: =COUNTIFS('📋 Entries'!$V$3:$V$302,$A10,'📋 Entries'!$P$3:$P$302,"<>")
A11: 8 | B11: =COUNTIF('📋 Entries'!$V$3:$V$302,$A11) | C11: =IFERROR(SUMPRODUCT((('📋 Entries'!$V$3:$V$302=$A11))/COUNTIFS('📋 Entries'!$B$3:$B$302,'📋 Entries'!$B$3:$B$302&"",'📋 Entries'!$V$3:$V$302,'📋 Entries'!$V$3:$V$302&"")),0) | D11: =COUNTIFS('📋 Entries'!$V$3:$V$302,$A11,'📋 Entries'!$I$3:$I$302,"Essential") | E11: =COUNTIFS('📋 Entries'!$V$3:$V$302,$A11,'📋 Entries'!$I$3:$I$302,"Barrier") | F11: =COUNTIFS('📋 Entries'!$V$3:$V$302,$A11,'📋 Entries'!$N$3:$N$302,"Diversion risk") | G11: =COUNTIFS('📋 Entries'!$V$3:$V$302,$A11,'📋 Entries'!$N$3:$N$302,"Growing loyalty") | H11: =COUNTIFS('📋 Entries'!$V$3:$V$302,$A11,'📋 Entries'!$L$3:$L$302,"<>") | I11: =COUNTIFS('📋 Entries'!$V$3:$V$302,$A11,'📋 Entries'!$P$3:$P$302,"<>")
A12: 9 | B12: =COUNTIF('📋 Entries'!$V$3:$V$302,$A12) | C12: =IFERROR(SUMPRODUCT((('📋 Entries'!$V$3:$V$302=$A12))/COUNTIFS('📋 Entries'!$B$3:$B$302,'📋 Entries'!$B$3:$B$302&"",'📋 Entries'!$V$3:$V$302,'📋 Entries'!$V$3:$V$302&"")),0) | D12: =COUNTIFS('📋 Entries'!$V$3:$V$302,$A12,'📋 Entries'!$I$3:$I$302,"Essential") | E12: =COUNTIFS('📋 Entries'!$V$3:$V$302,$A12,'📋 Entries'!$I$3:$I$302,"Barrier") | F12: =COUNTIFS('📋 Entries'!$V$3:$V$302,$A12,'📋 Entries'!$N$3:$N$302,"Diversion risk") | G12: =COUNTIFS('📋 Entries'!$V$3:$V$302,$A12,'📋 Entries'!$N$3:$N$302,"Growing loyalty") | H12: =COUNTIFS('📋 Entries'!$V$3:$V$302,$A12,'📋 Entries'!$L$3:$L$302,"<>") | I12: =COUNTIFS('📋 Entries'!$V$3:$V$302,$A12,'📋 Entries'!$P$3:$P$302,"<>")
A13: Total | B13: =SUM(B4:B12) | C13: see Summary tab | D13: =SUM(D4:D12) | E13: =SUM(E4:E12) | F13: =SUM(F4:F12) | G13: =SUM(G4:G12) | H13: =SUM(H4:H12) | I13: =SUM(I4:I12)

Sheet 👤 Participants
A1: PARTICIPANT TRACKER
A2: User Name | B2: Segment | C2: Start Date | D2: End Date | E2: Notes
A3: Richard | B3: M | C3: 46217
A4: Shania | B4: T | C4: 46217
A5: Kristin | B5: T | C5: 46212
A6: Tifany | B6: T | C6: 46212
A7: Deborah | B7: N | C7: 46212
A8: Joey | B8: M | C8: 46213
A9: Becky | B9: T | C9: 46213
A10: Annabelle | B10: N | C10: 46214
A11: Naomi | B11: M | C11: 46214
A12: Amy | B12: T | C12: 46216
A13: Colin | B13: T | C13: 46217
A14: Caroline | B14: M | C14: 46217
... A35: Dawn | B35: T | C35: 46225
